File: MaterialsAutomated0-CurieWeissAnalysis/140307 DCWb1131 Na1.9IrO3.dat
[Header]
; ACMS Data File (default extension .dat)
; Copyright 1999, Quantum Design, Inc. All rights reserved.
TITLE,Na1.9IrO3
FILEOPENTIME,37210026.02,03/07/2014,6:16 pm
BYAPP,ACMS,1.0,1.1
INFO,PPMS ACMS Option Version: 1.0.9 Build 14,APPNAME
INFO,HARMONICS,1
INFO,DCWb1131,Na1.9IrO3
INFO,mass (g) =,0.0467
INFO,,
INFO,,
INFO,,
INFO,,
INFO,,
INFO,,
INFO,,
INFO,,
DATATYPE,COMMENT,1
DATATYPE,TIME,2
FIELDGROUP,AC Mag,2,3,4,5,6,8,9,10,11,12
FIELDGROUP,DC Mag,2,3,4,7,8
STARTUPGROUP,All
STARTUPAXIS,X,2,LINEAR,AUTO
TIMEMODE,MINUTES,RELATIVE
PLOT_APPEARANCE,ALL,HORZ_GRID_ON,VERT_GRID_ON,MARKERS_AND_LINES
RECORDS,ALL_RECORDS
DATATYPE,TIME,2
DATATYPE,COMMENT,1
[Data]
Comment,Time Stamp (sec),Temperature (K),Magnetic Field (Oe),Frequency (Hz),Amplitude (Oe),M-DC (emu),M-Std.Dev. (emu),M' (emu),M'' (emu),Moment (emu),Phase (deg),Calcoil' (emu),Calcoil'' (emu),Calcoil (emu),CC Phase (deg),Count,Gain,Measure Type,Elapsed (sec),Sample Center (cm),Max.Signal (V),PPMS Status (code),DSP Status (code),Min.Temperature (K),Max.Temperature (K),Min.Field (Oe),Max.Field (Oe),DC Position (cm),PPMS Temperature (K),PPMS Position,Bridge 1 Resistance (ohms),Bridge 1 Excitation (uA),Bridge 2 Resistance (ohms),Bridge 2 Excitation (uA),Bridge 3 Resistance (ohms),Bridge 3 Excitation (uA),Bridge 4 Resistance (ohms),Bridge 4 Excitation (uA),Signal 1 Vin (V),Signal 2 Vin (V),Digital Inputs (code),Drive 1 Iout (mA),Drive 1 Ipower (watts),Drive 2 Iout (mA),Drive 2 Ipower (watts),Pressure (),Map 20 (),Map 21 (),Map 22 (),Map 23 (),Map 24 (),Map 25 (),Map 26 (),Map 27 (),Map 28 (),Map 29 ()
,37222591.25,1.7975027,10.092,10000,2.99843742042438,,0.122719120152632,,,,,,,,,,125,1,0,-0.176054710994559,0.000618489142196659,4374,0,1.7970427,1.7979627,10.092,10.092,,1.78785,,,,,,,,,,,,,,,,,,,,,,,1.7975027
,37222661.20,1.7984811,10.092,10000,2.99843742042438,,0.119998542148627,,,,,,,,,,125,1,0,-0.179957098499792,0.000618465854034872,4374,0,1.7981261,1.7988361,10.092,10.092,,1.78805,,,,,,,,,,,,,,,,,,,,,,,1.7984811
,37224814.92,1.98731265,9999.099,,,0.00428542130337945,0.000111322184931345,,,,,,,,,5,125,0,21.0420001298189,0.0347829246118735,5.98451075288673E-5,4373,0,1.9790691,1.9955562,9999.099,9999.099,0.0347829246118735,1.9652,,,,,,,,,,,,,,,,,,,,,,,1.98731265
,37224871.21,1.98563805,9999.099,,,0.00432868991646879,3.70378401786917E-5,,,,,,,,,5,125,0,21.1829996667802,0.0445190379357835,5.73616749083401E-5,4373,0,1.9767988,1.9944773,9999.099,9999.099,0.0445190379357835,1.96685,,,,,,,,,,,,,,,,,,,,,,,1.98563805
,37225134.11,3.0497427,9999.099,,,0.00424718148926984,4.07561837169179E-5,,,,,,,,,5,125,0,6.76400035154074,0.0445190379357835,5.70136658679558E-5,4370,0,3.0487654,3.05072,9999.099,9999.099,0.0346822828265392,3.03155,,,,,,,,,,,,,,,,,,,,,,,3.0497427
,37225381.52,5.0352571,9999.099,,,0.00410962771443175,4.11525809988691E-5,,,,,,,,,5,125,0,7.1229999884963,0.0445190379357835,5.66080875228282E-5,4370,0,5.0077672,5.062747,9999.099,9999.099,0.034989477362357,5.0106,,,,,,,,,,,,,,,,,,,,,,,5.0352571
,37225624.02,7.03658435,9999.099,,,0.00401721561682975,4.19382696134932E-5,,,,,,,,,5,125,0,6.28000013530254,0.0445190379357835,5.67023075561166E-5,4370,0,7.0129356,7.0602331,9999.099,9999.099,0.0338359314689241,7.0369,,,,,,,,,,,,,,,,,,,,,,,7.03658435
,37225867.22,9.03794,9999.099,,,0.00395491288222481,4.32558470409396E-5,,,,,,,,,5,125,0,7.1079999441281,0.0445190379357835,5.65123115623846E-5,4370,0,9.0065269,9.0693531,9999.099,9999.099,0.0294570022900507,9.05125,,,,,,,,,,,,,,,,,,,,,,,9.03794
,37226108.99,11.0464511,9999.099,,,0.00391121249720466,4.41765666969162E-5,,,,,,,,,5,125,0,7.01400025282055,0.0445190379357835,5.6649060271249E-5,4370,0,11.0186949,11.0742073,9999.099,9999.099,0.0160296987178425,11.06055,,,,,,,,,,,,,,,,,,,,,,,11.0464511
,37226348.53,13.03723095,9999.099,,,0.00392015953804397,4.42749112636942E-5,,,,,,,,,5,125,0,6.68599961791188,0.0445190379357835,5.6416016959556E-5,4370,0,13.012187,13.0622749,9999.099,9999.099,0.0296451710263954,13.0502,,,,,,,,,,,,,,,,,,,,,,,13.03723095
,37226590.36,15.04004525,9999.099,,,0.00392637335061785,4.39981880437771E-5,,,,,,,,,5,125,0,7.15499978978187,0.0445190379357835,5.66972940130609E-5,4370,0,15.0125847,15.0675058,9999.099,9999.099,-0.00636689310470735,15.0676,,,,,,,,,,,,,,,,,,,,,,,15.04004525
,37226831.13,17.04226115,9999.099,,,0.00395770552241866,4.37645314475235E-5,,,,,,,,,5,125,0,6.90499988850206,0.0445190379357835,5.69408765446673E-5,4370,0,17.0134583,17.071064,9999.099,9999.099,-0.0137068805199107,17.0675,,,,,,,,,,,,,,,,,,,,,,,17.04226115
,37227071.60,19.0365572,9999.099,,,0.0039381083263976,4.5240595973689E-5,,,,,,,,,5,125,0,6.4210003009066,0.0445190379357835,5.70857571900258E-5,4370,0,19.010437,19.0626774,9999.099,9999.099,-0.0313267790231751,19.06985,,,,,,,,,,,,,,,,,,,,,,,19.0365572
,37227313.42,21.04722785,9999.099,,,0.00391122296780788,4.55928880810413E-5,,,,,,,,,5,125,0,6.73300009220839,0.0445190379357835,5.71300126950626E-5,4370,0,21.0178566,21.0765991,9999.099,9999.099,-0.0303262289928372,21.0854,,,,,,,,,,,,,,,,,,,,,,,21.04722785
,37227552.64,23.0404234,9999.099,,,0.00386903932262218,4.65955689856865E-5,,,,,,,,,5,125,0,6.45199993159622,0.0445190379357835,5.71074737152996E-5,4370,0,23.013031,23.0678158,9999.099,9999.099,-0.0343479760752184,23.07575,,,,,,,,,,,,,,,,,,,,,,,23.0404234
,37227793.73,25.0422907,9999.099,,,0.00383278301741268,4.59313383537219E-5,,,,,,,,,5,125,0,7.16999983415008,0.0445190379357835,5.68777017488555E-5,4370,0,25.0089951,25.0755863,9999.099,9999.099,-0.0310111061583463,25.0957,,,,,,,,,,,,,,,,,,,,,,,25.0422907
,37228034.34,27.0396309,9999.099,,,0.00379315331270878,4.4794065924043E-5,,,,,,,,,5,125,0,6.95199973415583,0.0445190379357835,5.6565275846352E-5,4370,0,27.0106106,27.0686512,9999.099,9999.099,-0.0288343649828666,27.09485,,,,,,,,,,,,,,,,,,,,,,,27.0396309
,37228274.71,29.0377531,9999.099,,,0.00376578492337989,4.50466969191939E-5,,,,,,,,,5,125,0,6.5460002515465,0.0445190379357835,5.64595706493926E-5,4370,0,29.004612,29.0708942,9999.099,9999.099,-0.0284897616468758,29.0936,,,,,,,,,,,,,,,,,,,,,,,29.0377531
,37228516.38,31.05025105,9999.099,,,0.00372941692370559,4.5534241035378E-5,,,,,,,,,5,125,0,6.48299956228584,0.0445190379357835,5.62960431668892E-5,4370,0,31.0171185,31.0833836,9999.099,9999.099,-0.0298574395097526,31.11475,,,,,,,,,,,,,,,,,,,,,,,31.05025105
,37228754.19,33.0345192,9999.099,,,0.00370913909835436,4.83076735781904E-5,,,,,,,,,5,125,0,6.71799941919744,0.0445190379357835,5.61712914566151E-5,4370,0,33.0092125,33.0598259,9999.099,9999.099,-0.0374497945731754,33.0755,,,,,,,,,,,,,,,,,,,,,,,33.0345192
,37228994.05,35.0364895,9999.099,,,0.00366612695018395,4.86829273301917E-5,,,,,,,,,5,125,0,6.71699987724423,0.0445190379357835,5.59319154961877E-5,4370,0,35.0120468,35.0609322,9999.099,9999.099,-0.0366975249486705,35.076,,,,,,,,,,,,,,,,,,,,,,,35.0364895
,37229236.25,37.05587005,9999.099,,,0.00362835048078818,4.98759301786305E-5,,,,,,,,,5,125,0,6.90600005909801,0.0445190379357835,5.59259269778756E-5,4370,0,37.0167656,37.0949745,9999.099,9999.099,-0.0440642872110131,37.16295,,,,,,,,,,,,,,,,,,,,,,,37.05587005
,37229482.47,39.06333925,9999.099,,,0.0035714867978833,4.96443442484508E-5,,,,,,,,,5,125,0,6.95299990475178,0.0445190379357835,5.57135231487691E-5,4370,0,39.0039215,39.122757,9999.099,9999.099,-0.0437571463621725,39.29065,,,,,,,,,,,,,,,,,,,,,,,39.06333925
,37229714.84,41.0314236,9999.099,,,0.00354122906536513,5.03783257477451E-5,,,,,,,,,5,125,0,7.10999965667725,0.0445190379357835,5.54624938858075E-5,4370,0,41.0166588,41.0461884,9999.099,9999.099,-0.0444944939664029,41.039,,,,,,,,,,,,,,,,,,,,,,,41.0314236
,37229965.79,43.0757313,9999.099,,,0.00350869614212995,4.90970310715688E-5,,,,,,,,,5,125,0,6.82799995411187,0.0445190379357835,5.53009785182316E-5,4370,0,43.0147438,43.1367188,9999.099,9999.099,-0.0428335932929858,43.36545,,,,,,,,,,,,,,,,,,,,,,,43.0757313
,37230199.10,45.0566444,9999.099,,,0.00346689055181025,5.00827943648402E-5,,,,,,,,,5,125,0,7.04699959605932,0.0445190379357835,5.50049425186743E-5,4370,0,45.0093002,45.1039886,9999.099,9999.099,-0.0439411724746349,45.24815,,,,,,,,,,,,,,,,,,,,,,,45.0566444
,37230436.53,47.02190785,9999.099,,,0.00342997515966595,4.89544147490163E-5,,,,,,,,,5,125,0,6.4219998428598,0.0445190379357835,5.46140879303558E-5,4370,0,47.00383,47.0399857,9999.099,9999.099,-0.0420046601544667,47.03695,,,,,,,,,,,,,,,,,,,,,,,47.02190785
,37230689.41,49.04932785,9999.099,,,0.00340447652654822,4.75147928671589E-5,,,,,,,,,5,125,0,7.34399997163564,0.0445190379357835,5.42802056588004E-5,4370,0,49.0111885,49.0874672,9999.099,9999.099,-0.0367828719040901,49.2842,,,,,,,,,,,,,,,,,,,,,,,49.04932785
,37231142.94,55.01491925,9999.099,,,0.00327176176640005,4.54674869829136E-5,,,,,,,,,5,125,0,7.00000037904829,0.0445190379357835,5.47516455968443E-5,4370,0,55.0069351,55.0229034,9999.099,9999.099,-0.035539325941013,55.02035,,,,,,,,,,,,,,,,,,,,,,,55.01491925
,37231465.17,65.12120815,9999.099,,,0.00312864886612074,4.56823144461339E-5,,,,,,,,,5,125,0,6.9839995354414,0.0445190379357835,5.32086561021893E-5,4374,0,65.012886,65.2295303,9999.099,9999.099,-0.0362331951212636,66.51755,,,,,,,,,,,,,,,,,,,,,,,65.12120815
,37231770.68,75.145607,9999.099,,,0.0029766102426057,4.38914797426781E-5,,,,,,,,,5,125,0,6.96900011971593,0.0445190379357835,5.22900818552858E-5,4374,0,75.0343018,75.2569122,9999.099,9999.099,-0.0344661921637525,77.20955,,,,,,,,,,,,,,,,,,,,,,,75.145607
,37232075.48,85.16363905,9999.099,,,0.00282397791106774,4.48220763066104E-5,,,,,,,,,5,125,0,6.98499970603734,0.0445190379357835,5.17323032354893E-5,4374,0,85.0500412,85.2772369,9999.099,9999.099,-0.0393902143123597,87.7384,,,,,,,,,,,,,,,,,,,,,,,85.16363905
,37232379.03,95.1770973,9999.099,,,0.00268920969537332,4.5874589650817E-5,,,,,,,,,5,125,0,7.38999964669347,0.0445190379357835,5.10856354381458E-5,4374,0,95.0549469,95.2992477,9999.099,9999.099,-0.0453051591840189,98.0675,,,,,,,,,,,,,,,,,,,,,,,95.1770973
,37232682.61,105.1634636,9999.099,,,0.00258861192410839,4.70543537612205E-5,,,,,,,,,5,125,0,7.25000028032809,0.0445190379357835,5.05573190759507E-5,4374,0,105.0512009,105.2757263,9999.099,9999.099,-0.0458700416271535,108.6254,,,,,,,,,,,,,,,,,,,,,,,105.1634636
,37232985.45,115.14329145,9999.099,,,0.00246814281012571,4.76431055331922E-5,,,,,,,,,5,125,0,7.375000230968,0.0445190379357835,4.98207820178956E-5,4374,0,115.0154037,115.2711792,9999.099,9999.099,-0.0455445228595988,119.05985,,,,,,,,,,,,,,,,,,,,,,,115.14329145
,37233290.02,125.19020465,9999.099,,,0.00235861468364571,4.89073251760615E-5,,,,,,,,,5,125,0,6.95299990475178,0.0445190379357835,4.92821743881584E-5,4374,0,125.0805588,125.2998505,9999.099,9999.099,-0.0457163477870545,129.60425,,,,,,,,,,,,,,,,,,,,,,,125.19020465
,37233592.18,135.17382815,9999.099,,,0.00225688335497391,5.10407278745395E-5,,,,,,,,,5,125,0,6.73500043340027,0.0445190379357835,4.87452050162495E-5,4374,0,135.0622101,135.2854462,9999.099,9999.099,-0.0493312711410149,140.0365,,,,,,,,,,,,,,,,,,,,,,,135.17382815
,37233895.32,145.15010835,9999.099,,,0.00216365839632409,5.25634500293439E-5,,,,,,,,,5,125,0,6.70300000347197,0.0445190379357835,4.82012664925092E-5,4374,0,145.0382996,145.2619171,9999.099,9999.099,-0.0512027626701039,150.6354,,,,,,,,,,,,,,,,,,,,,,,145.15010835
,37234197.00,155.16117095,9999.099,,,0.00208128404395686,5.62484932835561E-5,,,,,,,,,5,125,0,7.10999965667725,0.0445190379357835,4.79367930707292E-5,4374,0,155.0482635,155.2740784,9999.099,9999.099,-0.0601568103413704,160.56205,,,,,,,,,,,,,,,,,,,,,,,155.16117095
,37234501.12,165.17944335,9999.099,,,0.00198931497036899,5.65783492378773E-5,,,,,,,,,5,125,0,6.70300000347197,0.0445190379357835,4.743369603208E-5,4374,0,165.0486603,165.3102264,9999.099,9999.099,-0.0631566399159533,171.68075,,,,,,,,,,,,,,,,,,,,,,,165.17944335
,37234805.61,175.16594695,9999.099,,,0.00192221657492409,5.89744561118795E-5,,,,,,,,,5,125,0,7.10900011472404,0.0445190379357835,4.69364911322553E-5,4374,0,175.0659027,175.2659912,9999.099,9999.099,-0.0677470382930634,182.4724,,,,,,,,,,,,,,,,,,,,,,,175.16594695
,37235106.80,185.1947403,9999.099,,,0.00184764205598064,5.84507368177546E-5,,,,,,,,,5,125,0,6.95299990475178,0.0445190379357835,4.65336721290496E-5,4374,0,185.0851746,185.304306,9999.099,9999.099,-0.0667770438919709,191.8468,,,,,,,,,,,,,,,,,,,,,,,185.1947403
,37235408.91,195.1506653,9999.099,,,0.00178058942634807,5.97460511933203E-5,,,,,,,,,5,125,0,7.15599996037781,0.0445190379357835,4.60897855356757E-5,4374,0,195.0396729,195.2616577,9999.099,9999.099,-0.0675725336948967,202.4835,,,,,,,,,,,,,,,,,,,,,,,195.1506653
,37235713.76,205.16143035,9999.099,,,0.00171644256114535,6.09751977366819E-5,,,,,,,,,5,125,0,6.57799942418933,0.0445190379357835,4.57423333337901E-5,4374,0,205.0494995,205.2733612,9999.099,9999.099,-0.0691505775980648,213.621,,,,,,,,,,,,,,,,,,,,,,,205.16143035
,37236017.71,215.2011032,9999.099,,,0.00165986182134278,6.65918863842304E-5,,,,,,,,,5,125,0,7.20299980603159,0.0445190379357835,4.54747917503682E-5,4374,0,215.0819702,215.3202362,9999.099,9999.099,-0.0813596776753961,224.30095,,,,,,,,,,,,,,,,,,,,,,,215.2011032
,37236317.67,225.15600585,9999.099,,,0.00161630576009888,7.21222500524762E-5,,,,,,,,,5,125,0,6.93700031843036,0.0445190379357835,4.53423017615076E-5,4374,0,225.0360718,225.2759399,9999.099,9999.099,-0.0897628457214095,233.9166,,,,,,,,,,,,,,,,,,,,,,,225.15600585
,37236622.14,235.1761856,9999.099,,,0.00155660163656884,7.21056017616277E-5,,,,,,,,,5,125,0,7.06199964042753,0.0445190379357835,4.48785633579639E-5,4374,0,235.0588226,235.2935486,9999.099,9999.099,-0.0931061627432584,244.7646,,,,,,,,,,,,,,,,,,,,,,,235.1761856
,37236924.43,245.1840744,9999.099,,,0.00150202406360712,7.83527476862691E-5,,,,,,,,,5,125,0,6.90700022969395,0.0445190379357835,4.47721817603788E-5,4374,0,245.0677948,245.300354,9999.099,9999.099,-0.103027117332411,254.30295,,,,,,,,,,,,,,,,,,,,,,,245.1840744
,37237225.22,255.16233825,9999.099,,,0.0014554897495185,7.90440170172019E-5,,,,,,,,,5,125,0,7.00000037904829,0.0445190379357835,4.42287348415761E-5,4374,0,255.0453186,255.2793579,9999.099,9999.099,-0.0988992140458206,264.36405,,,,,,,,,,,,,,,,,,,,,,,255.16233825
,37237530.77,265.1719208,9999.099,,,0.00140731884502668,7.81194322570114E-5,,,,,,,,,5,125,0,6.79699969477951,0.0445190379357835,4.39111096656248E-5,4374,0,265.0435181,265.3003235,9999.099,9999.099,-0.0990142292685417,275.38745,,,,,,,,,,,,,,,,,,,,,,,265.1719208
,37237835.03,275.18951415,9999.099,,,0.00134712199334775,8.1450606635661E-5,,,,,,,,,5,125,0,6.57800005283207,0.0445190379357835,4.37526192015921E-5,4374,0,275.0623474,275.3166809,9999.099,9999.099,-0.102820619835315,285.7586,,,,,,,,,,,,,,,,,,,,,,,275.18951415
,37238141.66,285.181015,9999.099,,,0.00130249666311604,8.54240220158666E-5,,,,,,,,,5,125,0,6.59399963915348,0.0445190379357835,4.33049989963163E-5,4374,0,285.0567627,285.3052673,9999.099,9999.099,-0.110612114800994,296.80125,,,,,,,,,,,,,,,,,,,,,,,285.181015
,37238445.20,295.1867828,9999.099,,,0.00127327975500952,8.96368527872095E-5,,,,,,,,,5,125,0,7.07799985539168,0.0445190379357835,4.31034496203333E-5,4374,0,295.0694885,295.3040771,9999.099,9999.099,-0.118883321631362,306.39065,,,,,,,,,,,,,,,,,,,,,,,295.1867828
,37239402.91,299.8509979,9999.099,,,0.00125018867822304,9.17258495815583E-5,,,,,,,,,5,125,0,6.5310002071783,0.0445190379357835,4.45602538745962E-5,4370,0,299.8346252,299.8673706,9999.099,9999.099,-0.131310205550444,300.7708,,,,,,,,,,,,,,,,,,,,,,,299.8509979
,37239874.33,289.7974243,9999.099,,,0.00127404765012736,9.23685091091282E-5,,,,,,,,,5,125,0,6.56300000846386,0.0445190379357835,5.32611221675271E-5,4374,0,289.6483154,289.9465332,9999.099,9999.099,-0.117530083984196,271.54185,,,,,,,,,,,,,,,,,,,,,,,289.7974243
,37240223.12,279.71755985,9999.099,,,0.0013292100299689,8.42159201843855E-5,,,,,,,,,5,125,0,6.84299999848008,0.0445190379357835,5.34736533633299E-5,4374,0,279.5230408,279.9120789,9999.099,9999.099,-0.102659628465734,263.9364,,,,,,,,,,,,,,,,,,,,,,,279.71755985
,37240565.83,269.6337433,9999.099,,,0.00136707220310412,7.99197061729027E-5,,,,,,,,,5,125,0,7.20399997662753,0.0445190379357835,5.21076161509507E-5,4374,0,269.3997803,269.8677063,9999.099,9999.099,-0.0922243804466545,260.0134,,,,,,,,,,,,,,,,,,,,,,,269.6337433
,37240901.37,259.73709105,9999.099,,,0.00141053814423403,7.4641502591408E-5,,,,,,,,,5,125,0,6.96799994911998,0.0445190379357835,4.95394578115E-5,4374,0,259.5572815,259.9169006,9999.099,9999.099,-0.0749041946620392,257.24975,,,,,,,,,,,,,,,,,,,,,,,259.73709105
,37241394.03,249.8832779,9999.099,,,0.00146345215502868,7.27305518080355E-5,,,,,,,,,5,125,0,6.95299990475178,0.0445190379357835,5.22751240346365E-5,4374,0,249.8053436,249.9612122,9999.099,9999.099,-0.0714593806886412,238.63595,,,,,,,,,,,,,,,,,,,,,,,249.8832779
,37241756.38,239.6835556,9999.099,,,0.00152355662200492,6.96380838327747E-5,,,,,,,,,5,125,0,7.07799985539168,0.0445190379357835,5.30373647839457E-5,4374,0,239.4850616,239.8820496,9999.099,9999.099,-0.0601705894596312,221.7517,,,,,,,,,,,,,,,,,,,,,,,239.6835556
,37242092.38,229.64967345,9999.099,,,0.00156746810457345,6.92034742390095E-5,,,,,,,,,5,125,0,6.93699968978763,0.0445190379357835,5.25275947624783E-5,4374,0,229.3790436,229.9203033,9999.099,9999.099,-0.0566977037366915,219.9163,,,,,,,,,,,,,,,,,,,,,,,229.64967345
,37242427.55,219.8302994,9999.099,,,0.00162455662628647,6.39766871254442E-5,,,,,,,,,5,125,0,6.92199964541942,0.0445190379357835,4.97114793668999E-5,4374,0,219.6986237,219.9619751,9999.099,9999.099,-0.0448904770783278,220.7936,,,,,,,,,,,,,,,,,,,,,,,219.8302994
,37242940.27,209.7078552,9999.099,,,0.00169944964856894,6.38402908808074E-5,,,,,,,,,5,125,0,6.96900011971593,0.0445190379357835,5.32949804160756E-5,4374,0,209.483078,209.9326324,9999.099,9999.099,-0.0442402401356141,194.3863,,,,,,,,,,,,,,,,,,,,,,,209.7078552
,37243263.78,199.63838195,9999.099,,,0.00175549812914962,6.11219654305783E-5,,,,,,,,,5,125,0,6.71899958979338,0.0445190379357835,5.31684578336E-5,4374,0,199.417984,199.8587799,9999.099,9999.099,-0.0439594606664446,193.9617,,,,,,,,,,,,,,,,,,,,,,,199.63838195
,37243748.59,189.78974915,9999.099,,,0.00183227361220027,6.00625798266648E-5,,,,,,,,,5,125,0,6.82900012470782,0.0445190379357835,5.32019888582498E-5,4374,0,189.6289673,189.950531,9999.099,9999.099,-0.0506545049879517,177.92395,,,,,,,,,,,,,,,,,,,,,,,189.78974915
,37244064.76,179.6029663,9999.099,,,0.00189540461021799,5.89476748931384E-5,,,,,,,,,5,125,0,6.62499989848584,0.0445190379357835,5.49332074445471E-5,4374,0,179.332489,179.8734436,9999.099,9999.099,-0.0491228649632989,172.06095,,,,,,,,,,,,,,,,,,,,,,,179.6029663
,37244527.30,169.7932587,9999.099,,,0.00195539035821709,5.86696540896295E-5,,,,,,,,,5,125,0,6.81299990974367,0.0445190379357835,5.49036309578301E-5,4374,0,169.6376038,169.9489136,9999.099,9999.099,-0.054326776724364,159.07785,,,,,,,,,,,,,,,,,,,,,,,169.7932587
,37244831.28,159.68022155,9999.099,,,0.00205692851118319,5.80006463541215E-5,,,,,,,,,5,125,0,7.29700012598187,0.0445190379357835,5.50694871525541E-5,4374,0,159.4478302,159.9126129,9999.099,9999.099,-0.0586355924025703,156.63385,,,,,,,,,,,,,,,,,,,,,,,159.68022155
,37245270.40,149.6565857,9999.099,,,0.00212187313520097,5.73778736196875E-5,,,,,,,,,5,125,0,7.1400003740564,0.0445190379357835,5.73972338147666E-5,4374,0,149.4461975,149.8669739,9999.099,9999.099,-0.064302028665294,139.0068,,,,,,,,,,,,,,,,,,,,,,,149.6565857
,37245674.35,139.81274415,9999.099,,,0.00221888706802293,6.03551364822378E-5,,,,,,,,,5,125,0,6.81300053838641,0.0445190379357835,5.8071065162754E-5,4374,0,139.6573334,139.9681549,9999.099,9999.099,-0.0430587143461806,132.1735,,,,,,,,,,,,,,,,,,,,,,,139.81274415
,37246054.98,129.87337495,9999.099,,,0.00230723289029566,6.28999856119046E-5,,,,,,,,,5,125,0,6.74999984912574,0.0445190379357835,5.96450873843279E-5,4374,0,129.7919159,129.954834,9999.099,9999.099,-0.042188866233028,125.53175,,,,,,,,,,,,,,,,,,,,,,,129.87337495
,37246429.60,119.8775406,9999.099,,,0.00241757622029079,6.18332249572089E-5,,,,,,,,,5,125,0,7.25000028032809,0.0445190379357835,5.95148766568974E-5,4374,0,119.796257,119.9588242,9999.099,9999.099,-0.0460145041175423,116.01675,,,,,,,,,,,,,,,,,,,,,,,119.8775406
,37246790.96,109.81897355,9999.099,,,0.00252041986655797,6.34879842728487E-5,,,,,,,,,5,125,0,6.45300010219216,0.0445190379357835,6.10722854964607E-5,4374,0,109.6992722,109.9386749,9999.099,9999.099,-0.0417732793769379,105.27265,,,,,,,,,,,,,,,,,,,,,,,109.81897355
,37247117.78,99.6567459,9999.099,,,0.00264483410011202,6.58021439513083E-5,,,,,,,,,5,125,0,7.40700003225356,0.0445190379357835,6.04724849861422E-5,4374,0,99.4580917,99.8554001,9999.099,9999.099,-0.0500632980029075,94.1312,,,,,,,,,,,,,,,,,,,,,,,99.6567459
,37247420.04,89.8492088,9999.099,,,0.00276481369876575,6.47425808095889E-5,,,,,,,,,5,125,0,7.18699959106743,0.0445190379357835,5.82451859788836E-5,4374,0,89.7659225,89.9324951,9999.099,9999.099,-0.0575049349196953,90.1637,,,,,,,,,,,,,,,,,,,,,,,89.8492088
,37270823.84,79.8883171,9999.099,,,0.00290069904299384,6.09662647317656E-5,,,,,,,,,5,125,0,6.56199983786792,0.0445190379357835,5.91995025337882E-5,4374,0,79.8120193,79.9646149,9999.099,9999.099,-0.0719201335148511,78.1435,,,,,,,,,,,,,,,,,,,,,,,79.8883171
,37271136.32,69.85142135,9999.099,,,0.00306311548982829,6.35468849746318E-5,,,,,,,,,5,125,0,6.74999984912574,0.0445190379357835,6.05699679815354E-5,4374,0,69.7605743,69.9422684,9999.099,9999.099,-0.0530049900183336,67.8712,,,,,,,,,,,,,,,,,,,,,,,69.85142135
,37271439.16,59.84324075,9999.099,,,0.00323938602346481,6.35782713411953E-5,,,,,,,,,5,125,0,7.14099991600961,0.0445190379357835,5.92958903604622E-5,4374,0,59.7585068,59.9279747,9999.099,9999.099,-0.0611656361982862,58.536,,,,,,,,,,,,,,,,,,,,,,,59.84324075
,37272771.18,50.06181905,9999.099,,,0.00341825673422454,6.62540296002616E-5,,,,,,,,,5,125,0,6.85900021344423,0.0445190379357835,5.67053192057218E-5,4370,0,50.049633,50.0740051,9999.099,9999.099,-0.0677154858230663,49.93855,,,,,,,,,,,,,,,,,,,,,,,50.06181905
,37273029.33,47.93517305,9999.099,,,0.00345904031839145,6.76451047525151E-5,,,,,,,,,5,125,0,6.62499989848584,0.0445190379357835,5.81783026109617E-5,4370,0,47.8954506,47.9748955,9999.099,9999.099,-0.0795930956139682,47.45065,,,,,,,,,,,,,,,,,,,,,,,47.93517305
,37273264.91,45.9339676,9999.099,,,0.00350090474456996,6.70593344013457E-5,,,,,,,,,5,125,0,7.15599996037781,0.0445190379357835,5.85401325611559E-5,4370,0,45.8984642,45.969471,9999.099,9999.099,-0.0697292002688449,45.58,,,,,,,,,,,,,,,,,,,,,,,45.9339676
,37273498.80,43.95832445,9999.099,,,0.00353152023807615,6.88751331213314E-5,,,,,,,,,5,125,0,7.31200017035007,0.0445190379357835,5.87554679107615E-5,4370,0,43.9389305,43.9777184,9999.099,9999.099,-0.0808656725210823,43.7129,,,,,,,,,,,,,,,,,,,,,,,43.95832445
,37273740.92,41.99307825,9999.099,,,0.00356482253361314,7.07405032175909E-5,,,,,,,,,5,125,0,6.99999975040555,0.0445190379357835,5.902950631349E-5,4370,0,41.9912262,41.9949303,9999.099,9999.099,-0.0730781763197058,41.8463,,,,,,,,,,,,,,,,,,,,,,,41.99307825
,37273979.28,39.9467354,9999.099,,,0.00360940502197051,6.96829108722552E-5,,,,,,,,,5,125,0,6.96799994911998,0.0445190379357835,5.91195472690319E-5,4370,0,39.9163208,39.97715,9999.099,9999.099,-0.0745888024157694,39.6666,,,,,,,,,,,,,,,,,,,,,,,39.9467354
,37274228.19,37.95106125,9999.099,,,0.00362920528162558,6.94337982590312E-5,,,,,,,,,5,125,0,6.17199994158,0.0445190379357835,5.94956087855863E-5,4370,0,37.9230461,37.9790764,9999.099,9999.099,-0.0745794553668077,37.6278,,,,,,,,,,,,,,,,,,,,,,,37.95106125
,37274454.00,35.9444313,9999.099,,,0.00368057728790064,7.21823067496658E-5,,,,,,,,,5,125,0,6.76600006408989,0.0445190379357835,5.97640697693042E-5,4370,0,35.9063148,35.9825478,9999.099,9999.099,-0.0799019695049485,35.726,,,,,,,,,,,,,,,,,,,,,,,35.9444313
,37274699.50,33.92393875,9999.099,,,0.0037151904594025,7.25639862012408E-5,,,,,,,,,5,125,0,7.10900011472404,0.0445190379357835,5.98149299172105E-5,4370,0,33.8837814,33.9640961,9999.099,9999.099,-0.0864545193519241,33.6819,,,,,,,,,,,,,,,,,,,,,,,33.92393875
,37274939.72,31.9185324,9999.099,,,0.00376063875935129,7.1615407791165E-5,,,,,,,,,5,125,0,7.12500032968819,0.0445190379357835,6.02275002738608E-5,4370,0,31.868639,31.9684258,9999.099,9999.099,-0.0786164750281074,31.68975,,,,,,,,,,,,,,,,,,,,,,,31.9185324
,37275176.04,29.945529,9999.099,,,0.00380466206559289,7.17883779140876E-5,,,,,,,,,5,125,0,6.76499989349395,0.0445190379357835,6.02694452300652E-5,4370,0,29.9140263,29.9770317,9999.099,9999.099,-0.077146045119055,29.75535,,,,,,,,,,,,,,,,,,,,,,,29.945529
,37275415.93,27.9837189,9999.099,,,0.00384575733168289,7.12796845060883E-5,,,,,,,,,5,125,0,6.67199974413961,0.0445190379357835,6.04952101458092E-5,4370,0,27.977026,27.9904118,9999.099,9999.099,-0.0759826786648311,27.8689,,,,,,,,,,,,,,,,,,,,,,,27.9837189
,37275654.00,25.96713635,9999.099,,,0.00387811225888676,7.03984435120986E-5,,,,,,,,,5,125,0,7.31300034094602,0.0445190379357835,6.06840166126032E-5,4370,0,25.9538059,25.9804668,9999.099,9999.099,-0.0755293347190474,25.84,,,,,,,,,,,,,,,,,,,,,,,25.96713635
,37275893.24,23.9714155,9999.099,,,0.00390833779255671,7.0567579445939E-5,,,,,,,,,5,125,0,6.96900011971593,0.0445190379357835,6.08449852086454E-5,4370,0,23.9601326,23.9826984,9999.099,9999.099,-0.0746477289120811,23.86235,,,,,,,,,,,,,,,,,,,,,,,23.9714155
,37276132.78,21.9817028,9999.099,,,0.00395199254470462,7.01276600059669E-5,,,,,,,,,5,125,0,6.67200037278235,0.0445190379357835,6.0973279761795E-5,4370,0,21.9753971,21.9880085,9999.099,9999.099,-0.0747049786331734,21.89225,,,,,,,,,,,,,,,,,,,,,,,21.9817028
,37276373.38,19.9823551,9999.099,,,0.00400031624226216,6.9955117964166E-5,,,,,,,,,5,125,0,6.56300000846386,0.0445190379357835,6.10507259372276E-5,4370,0,19.971941,19.9927692,9999.099,9999.099,-0.0745410684248068,19.8955,,,,,,,,,,,,,,,,,,,,,,,19.9823551
,37276615.54,17.969326,9999.099,,,0.0040290359589682,6.95779102446417E-5,,,,,,,,,5,125,0,6.67200037278235,0.0445190379357835,6.10785486963883E-5,4370,0,17.9543686,17.9842834,9999.099,9999.099,-0.0738319246377981,17.8665,,,,,,,,,,,,,,,,,,,,,,,17.969326
,37276853.18,15.9723744,9999.099,,,0.0040414419692995,6.98065826236969E-5,,,,,,,,,5,125,0,6.57800005283207,0.0445190379357835,6.07916298816266E-5,4370,0,15.9598436,15.9849052,9999.099,9999.099,-0.0734380265655022,15.88415,,,,,,,,,,,,,,,,,,,,,,,15.9723744
,37277093.20,13.9776344,9999.099,,,0.00400496355784685,6.98570554552997E-5,,,,,,,,,5,125,0,7.15700013097376,0.0445190379357835,6.06804675304258E-5,4370,0,13.9680967,13.9871721,9999.099,9999.099,-0.0740179405892298,13.894,,,,,,,,,,,,,,,,,,,,,,,13.9776344
,37277335.94,11.97951265,9999.099,,,0.00399310843476549,6.95482790480836E-5,,,,,,,,,5,125,0,6.88999984413385,0.0445190379357835,6.05634272321942E-5,4370,0,11.9676208,11.9914045,9999.099,9999.099,-0.0718618383080828,11.91385,,,,,,,,,,,,,,,,,,,,,,,11.97951265
,37277615.74,9.98347615,9999.099,,,0.00402623388777358,7.01416848517553E-5,,,,,,,,,5,125,0,6.73499980475754,0.0445190379357835,6.05914339209882E-5,4370,0,9.977684,9.9892683,9999.099,9999.099,-0.0748140376716597,9.91715,,,,,,,,,,,,,,,,,,,,,,,9.98347615
,37277893.70,7.96480085,9999.099,,,0.00408119233542896,7.23139114783616E-5,,,,,,,,,5,125,0,6.84400016907603,0.0445190379357835,6.11213135577383E-5,4370,0,7.9474864,7.9821153,9999.099,9999.099,-0.0813851747587585,7.9475,,,,,,,,,,,,,,,,,,,,,,,7.96480085
,37278177.19,5.96924185,9999.099,,,0.00415582613676412,7.33888888289363E-5,,,,,,,,,5,125,0,6.01500018965453,0.0445190379357835,6.12725842533848E-5,4370,0,5.9575496,5.9809341,9999.099,9999.099,-0.0943406212726305,5.9596,,,,,,,,,,,,,,,,,,,,,,,5.96924185
,37278476.57,3.953895,9999.099,,,0.00429344578715553,7.23751421372234E-5,,,,,,,,,5,125,0,6.70300000347197,0.0445190379357835,6.2240198063137E-5,4370,0,3.9314728,3.9763172,9999.099,9999.099,-0.0858405114322723,3.94965,,,,,,,,,,,,,,,,,,,,,,,3.953895
,37278759.26,1.99780105,9999.099,,,0.00443794427216509,6.86476027140752E-5,,,,,,,,,5,125,0,6.70300000347197,0.0445190379357835,6.22989775334453E-5,4370,0,1.9965447,1.9990574,9999.099,9999.099,-0.0926816129155382,1.9826,,,,,,,,,,,,,,,,,,,,,,,1.99780105
,37287650.65,1.7941984,9.853,1000,10.0020797429327,,0.122353900223559,,,,,,,,,,125,1,0,-0.197932147240252,0.000134880214833718,4373,0,1.7937225,1.7946743,9.853,9.853,,1.7854,,,,,,,,,,,,,,,,,,,,,,,1.7941984
,37287718.72,1.7952226,9.853,1000,10.0020797429327,,0.130893320637192,,,,,,,,,,125,1,0,-0.188409735891905,0.000134950079319081,4374,0,1.794975,1.7954702,9.853,9.853,,1.78595,,,,,,,,,,,,,,,,,,,,,,,1.7952226
,37287926.08,2.3901710875,9.853,100,5.00030447701092,,4.3269427175411E-8,2.42624746742739E-6,-4.27728212498153E-8,2.42662446361926E-6,-1.00997459326675,1.51698330883383E-8,-7.92122249256596E-12,1.51698351564481E-8,-0.0299180995279471,800,25,5,13.4965986394558,-0.188409735891905,8.54097348762491E-5,4370,0,2.322588,2.4556808,9.853,9.853,,2.377425,,,,,,,,,,,,,,,,,,,,,,,2.3901710875
,37288046.10,3.3828802625,9.853,100,5.00030447701092,,3.16137162876525E-8,2.34259507375137E-6,9.68441190407097E-9,2.34261509160129E-6,0.236862432779491,1.51687555713517E-8,-7.87783937079882E-12,1.51687576170155E-8,-0.0297563570672992,800,25,5,13.4965986394558,-0.188409735891905,8.52950607554465E-5,4374,0,3.3139069,3.4490657,9.853,9.853,,3.3189125,,,,,,,,,,,,,,,,,,,,,,,3.3828802625
,37288173.72,4.3929802375,9.853,100,5.00030447701092,,5.27446455188088E-8,2.14544690785407E-6,-6.03578288426885E-8,2.1462957629188E-6,-1.61147633750591,1.51645299057755E-8,-7.5280445969429E-12,1.51645317743284E-8,-0.0284430279500612,800,25,5,13.4965986394558,-0.188409735891905,8.52712907696218E-5,4370,0,4.3210516,4.461019,9.853,9.853,,4.406375,,,,,,,,,,,,,,,,,,,,,,,4.3929802375
,37288294.87,5.387885825,9.853,100,5.00030447701092,,5.01339644801009E-8,2.21145393285372E-6,7.12003327823878E-8,2.21259982475877E-6,1.84406728875354,1.51653092039872E-8,-7.91369426811387E-12,1.51653112687837E-8,-0.0298985819982249,800,25,5,13.4965986394558,-0.188409735891905,8.51993383800986E-5,4370,0,5.3161817,5.4593368,9.853,9.853,,5.409275,,,,,,,,,,,,,,,,,,,,,,,5.387885825
,37288414.97,6.3890426875,9.853,100,5.00030447701092,,2.96902847232645E-8,2.12079848799082E-6,3.19478315114629E-8,2.12103910633501E-6,0.863041669753855,1.51650816032648E-8,-7.46616061558942E-12,1.51650834411564E-8,-0.0282081870093975,800,25,5,13.4965986394558,-0.188409735891905,8.51010462765535E-5,4370,0,6.3224549,6.4602151,9.853,9.853,,6.3960625,,,,,,,,,,,,,,,,,,,,,,,6.3890426875
,37288534.30,7.3753681125,9.853,100,5.00030447701092,,3.69968568400782E-8,2.14553148096726E-6,8.42351587276107E-8,2.14718441168602E-6,2.24832012168317,1.51647450714718E-8,-7.80959981245348E-12,1.51647470823808E-8,-0.0295064023347891,800,25,5,13.4965986394558,-0.188409735891905,8.50779187227782E-5,4370,0,7.3028297,7.447001,9.853,9.853,,7.3772875,,,,,,,,,,,,,,,,,,,,,,,7.3753681125
,37288654.02,8.371576575,9.853,100,5.00030447701092,,4.64429606390991E-8,2.21700581513447E-6,3.39482773047014E-8,2.21726571927498E-6,0.877282771354396,1.516416248575E-8,-7.68133919327616E-12,1.5164164431224E-8,-0.0290229202934711,800,25,5,13.4965986394558,-0.188409735891905,8.50596094093727E-5,4370,0,8.293767,8.4371281,9.853,9.853,,8.3743,,,,,,,,,,,,,,,,,,,,,,,8.371576575
,37288774.68,9.3712871125,9.853,100,5.00030447701092,,6.43719881656135E-8,2.07131867440948E-6,4.93226785603463E-8,2.07190583221772E-6,1.36408144323375,1.5165106633345E-8,-8.20733088932896E-12,1.51651088542418E-8,-0.0310083790694193,800,25,5,13.4965986394558,-0.188409735891905,8.5618846508301E-5,4370,0,9.3033047,9.4349709,9.853,9.853,,9.378525,,,,,,,,,,,,,,,,,,,,,,,9.3712871125
,37288896.10,10.3744349375,9.853,100,5.00030447701092,,7.62129234250004E-8,2.08747129508133E-6,2.27707074498801E-8,2.08759548593742E-6,0.6249732356118,1.5164763831105E-8,-7.97901533736114E-12,1.5164765930204E-8,-0.030146454399528,800,25,5,13.4965986394558,-0.188409735891905,8.55584578956654E-5,4370,0,10.3054523,10.4430122,9.853,9.853,,10.3835625,,,,,,,,,,,,,,,,,,,,,,,10.3744349375
,37289015.71,11.3624997125,9.853,100,5.00030447701092,,2.17004460494214E-8,2.08283388373913E-6,1.50654211996295E-8,2.08288836814836E-6,0.414420950749141,1.51643091152792E-8,-8.32120654866806E-12,1.5164311398353E-8,-0.0314402696632783,800,25,5,13.4965986394558,-0.188409735891905,8.55150937323367E-5,4370,0,11.2999535,11.425539,9.853,9.853,,11.3761625,,,,,,,,,,,,,,,,,,,,,,,11.3624997125
,37289137.28,12.3703617875,9.853,100,5.00030447701092,,4.37865535216564E-8,2.19235166941152E-6,9.35257241836976E-8,2.19434566635605E-6,2.44275688592875,1.51632280156168E-8,-8.96459990954056E-12,1.51632306655817E-8,-0.0338736368976811,800,25,5,13.4965986394558,-0.188409735891905,8.5448280799208E-5,4370,0,12.3012743,12.4440508,9.853,9.853,,12.3935,,,,,,,,,,,,,,,,,,,,,,,12.3703617875
,37289256.07,13.3615925375,9.853,100,5.00030447701092,,5.68687699393335E-8,2.03841790574572E-6,8.14778583827115E-8,2.04004563671291E-6,2.28895830918758,1.51639755440962E-8,-7.41466181666257E-12,1.51639773568532E-8,-0.0280156607690856,800,25,5,13.4965986394558,-0.188409735891905,8.52385267351068E-5,4370,0,13.2860661,13.4296064,9.853,9.853,,13.37485,,,,,,,,,,,,,,,,,,,,,,,13.3615925375
,37289375.92,14.3520491125,9.853,100,5.00030447701092,,5.83179474901356E-8,2.1277509966173E-6,1.1032119194998E-7,2.13060908404126E-6,2.96805577531996,1.51649400471043E-8,-8.59712940839412E-12,1.51649424839958E-8,-0.03248144580391,800,25,5,13.4965986394558,-0.188409735891905,8.5609531243586E-5,4370,0,14.2888107,14.4187918,9.853,9.853,,14.3772875,,,,,,,,,,,,,,,,,,,,,,,14.3520491125