File: MaterialsAutomated0-CurieWeissAnalysis/140309 DCWb1133 Na1.7IrO3.dat
[Header]
; ACMS Data File (default extension .dat)
; Copyright 1999, Quantum Design, Inc. All rights reserved.
TITLE,Na1.7IrO3
FILEOPENTIME,37363665.16,03/09/2014,1:56 pm
BYAPP,ACMS,1.0,1.1
INFO,PPMS ACMS Option Version: 1.0.9 Build 14,APPNAME
INFO,HARMONICS,1
INFO,DCWb1132,Na1.8IrO3
INFO,mass (g) =,0.0337
INFO,,
INFO,,
INFO,,
INFO,,
INFO,,
INFO,,
INFO,,
INFO,,
DATATYPE,COMMENT,1
DATATYPE,TIME,2
FIELDGROUP,AC Mag,2,3,4,5,6,8,9,10,11,12
FIELDGROUP,DC Mag,2,3,4,7,8
STARTUPGROUP,All
STARTUPAXIS,X,2,LINEAR,AUTO
TIMEMODE,MINUTES,RELATIVE
PLOT_APPEARANCE,ALL,HORZ_GRID_ON,VERT_GRID_ON,MARKERS_AND_LINES
RECORDS,ALL_RECORDS
DATATYPE,TIME,2
DATATYPE,COMMENT,1
[Data]
Comment,Time Stamp (sec),Temperature (K),Magnetic Field (Oe),Frequency (Hz),Amplitude (Oe),M-DC (emu),M-Std.Dev. (emu),M' (emu),M'' (emu),Moment (emu),Phase (deg),Calcoil' (emu),Calcoil'' (emu),Calcoil (emu),CC Phase (deg),Count,Gain,Measure Type,Elapsed (sec),Sample Center (cm),Max.Signal (V),PPMS Status (code),DSP Status (code),Min.Temperature (K),Max.Temperature (K),Min.Field (Oe),Max.Field (Oe),DC Position (cm),PPMS Temperature (K),PPMS Position,Bridge 1 Resistance (ohms),Bridge 1 Excitation (uA),Bridge 2 Resistance (ohms),Bridge 2 Excitation (uA),Bridge 3 Resistance (ohms),Bridge 3 Excitation (uA),Bridge 4 Resistance (ohms),Bridge 4 Excitation (uA),Signal 1 Vin (V),Signal 2 Vin (V),Digital Inputs (code),Drive 1 Iout (mA),Drive 1 Ipower (watts),Drive 2 Iout (mA),Drive 2 Ipower (watts),Pressure (),Map 20 (),Map 21 (),Map 22 (),Map 23 (),Map 24 (),Map 25 (),Map 26 (),Map 27 (),Map 28 (),Map 29 ()
,37376184.59,1.7961695,10.026,10000,2.99843742220581,,0.158670149247715,,,,,,,,,,125,1,0,0.0300320573575457,0.000497844552375701,4373,0,1.7957605,1.7965785,10.026,10.026,,1.7867,,,,,,,,,,,,,,,,,,,,,,,1.7961695
,37376253.81,1.795044,10.026,10000,2.99843742220581,,0.14137642333794,,,,,,,,,,125,1,0,0.016922652707684,0.000498026307109653,4373,0,1.794566,1.795522,10.026,10.026,,1.7855,,,,,,,,,,,,,,,,,,,,,,,1.795044
,37378409.54,1.99806675,9998.583,,,0.00251204815507392,0.000111369803862893,,,,,,,,,5,125,0,20.5790003528818,0.283839638307667,5.16286134962162E-5,4373,0,1.9948363,2.0012972,9998.583,9998.583,0.283839638307667,1.9829,,,,,,,,,,,,,,,,,,,,,,,1.99806675
,37378466.84,1.9882134,9998.583,,,0.0025183726080703,3.69607905936151E-5,,,,,,,,,5,125,0,21.968999854289,0.244529890764881,5.09218766485633E-5,4373,0,1.9822514,1.9941754,9998.583,9998.583,0.244529890764881,1.98225,,,,,,,,,,,,,,,,,,,,,,,1.9882134
,37378727.81,3.0320369,9998.583,,,0.00241633514906582,4.54320497088931E-5,,,,,,,,,5,125,0,6.76600006408989,0.244529890764881,5.04746339321058E-5,4370,0,3.0133672,3.0507066,9998.583,9998.583,0.230251676048335,3.0466,,,,,,,,,,,,,,,,,,,,,,,3.0320369
,37378972.13,5.04008725,9998.583,,,0.00228459086545911,4.88372190129475E-5,,,,,,,,,5,125,0,7.18800039030611,0.244529890764881,5.02415905684472E-5,4370,0,5.0107117,5.0694628,9998.583,9998.583,0.224435342051425,5.0505,,,,,,,,,,,,,,,,,,,,,,,5.04008725
,37379213.42,7.04953835,9998.583,,,0.00220015709418007,5.06053332122619E-5,,,,,,,,,5,125,0,7.12500032968819,0.244529890764881,4.97981512303284E-5,4370,0,7.0192494,7.0798273,9998.583,9998.583,0.227693455052515,7.0462,,,,,,,,,,,,,,,,,,,,,,,7.04953835
,37379456.17,9.0532298,9998.583,,,0.00213850647354842,5.05752115680703E-5,,,,,,,,,5,125,0,6.73499980475754,0.244529890764881,4.96875074968407E-5,4370,0,9.0216446,9.084815,9998.583,9998.583,0.230852249089714,9.06355,,,,,,,,,,,,,,,,,,,,,,,9.0532298
,37379695.67,11.0381818,9998.583,,,0.00208636733749717,5.04141535957208E-5,,,,,,,,,5,125,0,6.73500043340027,0.244529890764881,4.96301110600939E-5,4370,0,11.0137596,11.062604,9998.583,9998.583,0.231502127514205,11.0488,,,,,,,,,,,,,,,,,,,,,,,11.0381818
,37379936.63,13.0352616,9998.583,,,0.00210422851047667,4.99299225824099E-5,,,,,,,,,5,125,0,7.25000028032809,0.244529890764881,4.97986698728291E-5,4370,0,13.0085754,13.0619478,9998.583,9998.583,0.236161072822527,13.0508,,,,,,,,,,,,,,,,,,,,,,,13.0352616
,37380178.38,15.03664875,9998.583,,,0.00209106089046755,5.0464520561415E-5,,,,,,,,,5,125,0,6.71899958979338,0.244529890764881,4.99215881455007E-5,4370,0,15.0107918,15.0625057,9998.583,9998.583,0.235014050580984,15.0691,,,,,,,,,,,,,,,,,,,,,,,15.03664875
,37380418.71,17.03899765,9998.583,,,0.00209727751344232,4.77313328235871E-5,,,,,,,,,5,125,0,6.93699968978763,0.244529890764881,4.9847382630899E-5,4370,0,17.0126667,17.0653286,9998.583,9998.583,0.236286060895769,17.0668,,,,,,,,,,,,,,,,,,,,,,,17.03899765
,37380659.63,19.0395374,9998.583,,,0.00209138431912502,4.84435705405886E-5,,,,,,,,,5,125,0,6.8910000147298,0.244529890764881,4.97732541224813E-5,4370,0,19.0135269,19.0655479,9998.583,9998.583,0.233111530492798,19.0713,,,,,,,,,,,,,,,,,,,,,,,19.0395374
,37380899.94,21.03233435,9998.583,,,0.00206469836607797,4.83905264542799E-5,,,,,,,,,5,125,0,6.64100011344999,0.244529890764881,4.98727638981246E-5,4370,0,21.0060997,21.058569,9998.583,9998.583,0.233911485683629,21.0752,,,,,,,,,,,,,,,,,,,,,,,21.03233435
,37381140.81,23.0407028,9998.583,,,0.00203725964083894,4.95027140840953E-5,,,,,,,,,5,125,0,6.73499980475754,0.244529890764881,4.97847403651531E-5,4370,0,23.0132236,23.068182,9998.583,9998.583,0.23356942116356,23.08145,,,,,,,,,,,,,,,,,,,,,,,23.0407028
,37381381.53,25.04283615,9998.583,,,0.00201247668916091,4.77097180612765E-5,,,,,,,,,5,125,0,7.14099991600961,0.244529890764881,4.98252831007579E-5,4370,0,25.0118465,25.0738258,9998.583,9998.583,0.235479944883646,25.09135,,,,,,,,,,,,,,,,,,,,,,,25.04283615
,37381623.39,27.0469961,9998.583,,,0.00199383938470338,4.9439351584031E-5,,,,,,,,,5,125,0,7.06299981102347,0.244529890764881,4.94947112722356E-5,4370,0,27.0174541,27.0765381,9998.583,9998.583,0.240801549244418,27.11485,,,,,,,,,,,,,,,,,,,,,,,27.0469961
,37381862.99,29.04036715,9998.583,,,0.001962076343134,4.89972488394301E-5,,,,,,,,,5,125,0,7.09400007035583,0.244529890764881,4.93539991977771E-5,4370,0,29.013773,29.0669613,9998.583,9998.583,0.235982837097728,29.08155,,,,,,,,,,,,,,,,,,,,,,,29.04036715
,37382102.28,31.03447435,9998.583,,,0.001933696163802,5.09621839183296E-5,,,,,,,,,5,125,0,6.82799995411187,0.244529890764881,4.92755525308318E-5,4370,0,31.0056934,31.0632553,9998.583,9998.583,0.23962971447214,31.0905,,,,,,,,,,,,,,,,,,,,,,,31.03447435
,37382344.33,33.03433605,9998.583,,,0.00192925531306375,5.06312073994469E-5,,,,,,,,,5,125,0,6.56300000846386,0.244529890764881,4.91338902230656E-5,4370,0,33.0116882,33.0569839,9998.583,9998.583,0.232203424696203,33.0809,,,,,,,,,,,,,,,,,,,,,,,33.03433605
,37382585.75,35.0398426,9998.583,,,0.0018826274713485,5.13458591208331E-5,,,,,,,,,5,125,0,7.32799975667149,0.244529890764881,4.90147753246649E-5,4370,0,35.0105705,35.0691147,9998.583,9998.583,0.235124924462314,35.10265,,,,,,,,,,,,,,,,,,,,,,,35.0398426
,37382823.02,37.02947995,9998.583,,,0.00187138117762142,5.19217752799125E-5,,,,,,,,,5,125,0,7.03100000973791,0.244529890764881,4.87611877248687E-5,4370,0,37.006813,37.0521469,9998.583,9998.583,0.233955134082238,37.0742,,,,,,,,,,,,,,,,,,,,,,,37.02947995
,37383065.84,39.0545826,9998.583,,,0.00186115320398439,5.16035061950021E-5,,,,,,,,,5,125,0,6.74999984912574,0.244529890764881,4.85249162035922E-5,4370,0,39.0161591,39.0930061,9998.583,9998.583,0.230745515813159,39.18035,,,,,,,,,,,,,,,,,,,,,,,39.0545826
,37383312.02,41.0534115,9998.583,,,0.00182577644209888,5.09051530332813E-5,,,,,,,,,5,125,0,6.7810001084581,0.244529890764881,4.83712486032785E-5,4370,0,41.0086174,41.0982056,9998.583,9998.583,0.233918566903496,41.26305,,,,,,,,,,,,,,,,,,,,,,,41.0534115
,37383546.37,43.0520363,9998.583,,,0.00179459665191876,5.16690769983305E-5,,,,,,,,,5,125,0,6.81199973914772,0.244529890764881,4.81160167288698E-5,4370,0,43.0180321,43.0860405,9998.583,9998.583,0.234768497400812,43.17885,,,,,,,,,,,,,,,,,,,,,,,43.0520363
,37383791.37,45.03295135,9998.583,,,0.0017840388851791,5.18860202848119E-5,,,,,,,,,5,125,0,6.45300010219216,0.244529890764881,4.81328634215386E-5,4370,0,45.0058365,45.0600662,9998.583,9998.583,0.230687274867794,45.16205,,,,,,,,,,,,,,,,,,,,,,,45.03295135
,37384033.51,47.0642853,9998.583,,,0.0017642732715962,5.2529725374384E-5,,,,,,,,,5,125,0,6.99999975040555,0.244529890764881,4.79822275569213E-5,4370,0,47.0173836,47.111187,9998.583,9998.583,0.230511532317209,47.33185,,,,,,,,,,,,,,,,,,,,,,,47.0642853
,37384270.77,49.05539705,9998.583,,,0.00174661282505751,4.89773994848734E-5,,,,,,,,,5,125,0,6.74999984912574,0.244529890764881,4.76298192882238E-5,4370,0,49.0151482,49.0956459,9998.583,9998.583,0.239550512322187,49.2839,,,,,,,,,,,,,,,,,,,,,,,49.05539705
,37384901.01,55.03381345,9998.583,,,0.00168569560679936,4.72787152852039E-5,,,,,,,,,5,125,0,7.17200017534196,0.244529890764881,4.7342075914782E-5,4370,0,55.0250282,55.0425987,9998.583,9998.583,0.239142658620588,55.03575,,,,,,,,,,,,,,,,,,,,,,,55.03381345
,37385222.16,65.13946155,9998.583,,,0.0015911639382247,4.82691784713788E-5,,,,,,,,,5,125,0,7.26599986664951,0.244529890764881,4.66839873485958E-5,4374,0,65.0415955,65.2373276,9998.583,9998.583,0.243655242272828,66.5212,,,,,,,,,,,,,,,,,,,,,,,65.13946155
,37385526.72,75.1480942,9998.583,,,0.00151312297674752,5.21226959980143E-5,,,,,,,,,5,125,0,7.17100000474602,0.244529890764881,4.61279107953905E-5,4374,0,75.0269318,75.2692566,9998.583,9998.583,0.229286181037128,77.11025,,,,,,,,,,,,,,,,,,,,,,,75.1480942
,37385831.86,85.1817856,9998.583,,,0.00142747729056158,5.3881194340525E-5,,,,,,,,,5,125,0,7.57900045718998,0.244529890764881,4.573591848503E-5,4374,0,85.0554581,85.3081131,9998.583,9998.583,0.238505953814043,87.6219,,,,,,,,,,,,,,,,,,,,,,,85.1817856
,37386134.57,95.1638565,9998.583,,,0.00135149549747942,5.49082417932985E-5,,,,,,,,,5,125,0,7.18800039030611,0.244529890764881,4.528327868337E-5,4374,0,95.0319519,95.2957611,9998.583,9998.583,0.242170300765033,98.1044,,,,,,,,,,,,,,,,,,,,,,,95.1638565
,37386438.33,105.1625595,9998.583,,,0.00130571079095566,5.80239412387197E-5,,,,,,,,,5,125,0,7.1089994860813,0.244529890764881,4.47233533849721E-5,4374,0,105.0408859,105.2842331,9998.583,9998.583,0.240123477852285,108.56205,,,,,,,,,,,,,,,,,,,,,,,105.1625595
,37386742.44,115.17575455,9998.583,,,0.00121960919739796,6.0796530095847E-5,,,,,,,,,5,125,0,6.8910000147298,0.244529890764881,4.42432389094237E-5,4374,0,115.0516052,115.2999039,9998.583,9998.583,0.240343777428595,119.0699,,,,,,,,,,,,,,,,,,,,,,,115.17575455
,37387045.30,125.15879445,9998.583,,,0.00117157502466995,6.44169973226149E-5,,,,,,,,,5,125,0,6.68799995910376,0.244529890764881,4.40017775932272E-5,4374,0,125.0490952,125.2684937,9998.583,9998.583,0.236557103198744,129.5119,,,,,,,,,,,,,,,,,,,,,,,125.15879445
,37387349.05,135.1809921,9998.583,,,0.00112452192507521,6.55677251241573E-5,,,,,,,,,5,125,0,6.8589995848015,0.244529890764881,4.35205304939973E-5,4374,0,135.0743713,135.2876129,9998.583,9998.583,0.235217205714898,140.03595,,,,,,,,,,,,,,,,,,,,,,,135.1809921
,37387651.44,145.17154695,9998.583,,,0.00107618936766717,6.85884937322355E-5,,,,,,,,,5,125,0,6.84400016907603,0.244529890764881,4.32506361333007E-5,4374,0,145.0588379,145.284256,9998.583,9998.583,0.231076309992698,150.59475,,,,,,,,,,,,,,,,,,,,,,,145.17154695
,37387953.50,155.16762545,9998.583,,,0.00102393472031046,7.06986444923366E-5,,,,,,,,,5,125,0,6.56199983786792,0.244529890764881,4.27396441858904E-5,4374,0,155.0652161,155.2700348,9998.583,9998.583,0.227349453922275,160.88255,,,,,,,,,,,,,,,,,,,,,,,155.16762545
,37388257.27,165.162735,9998.583,,,0.000982151956112511,7.61260621092356E-5,,,,,,,,,5,125,0,6.95299990475178,0.244529890764881,4.24929115611031E-5,4374,0,165.0549774,165.2704926,9998.583,9998.583,0.227286244659774,171.6177,,,,,,,,,,,,,,,,,,,,,,,165.162735
,37388558.31,175.16085055,9998.583,,,0.000936309192356811,7.86835226212935E-5,,,,,,,,,5,125,0,7.12500032968819,0.244529890764881,4.23293531137564E-5,4374,0,175.0415497,175.2801514,9998.583,9998.583,0.225511788957506,180.932,,,,,,,,,,,,,,,,,,,,,,,175.16085055
,37388863.06,185.1755371,9998.583,,,0.000902830826165415,7.94193542141844E-5,,,,,,,,,5,125,0,6.85900021344423,0.244529890764881,4.20336392484494E-5,4374,0,185.0561371,185.2949371,9998.583,9998.583,0.220659383213786,192.2986,,,,,,,,,,,,,,,,,,,,,,,185.1755371
,37389165.44,195.17803955,9998.583,,,0.000858888663434184,8.38431989985515E-5,,,,,,,,,5,125,0,7.14099991600961,0.244529890764881,4.16631774200881E-5,4374,0,195.0500336,195.3060455,9998.583,9998.583,0.217774472692397,203.0923,,,,,,,,,,,,,,,,,,,,,,,195.17803955
,37389465.83,205.12548065,9998.583,,,0.000837645357822596,8.46681138435495E-5,,,,,,,,,5,125,0,6.7810001084581,0.244529890764881,4.12769577459029E-5,4374,0,205.0216522,205.2293091,9998.583,9998.583,0.213948326728448,211.4121,,,,,,,,,,,,,,,,,,,,,,,205.12548065
,37389772.46,215.1630783,9998.583,,,0.000807980202838876,8.50932185426885E-5,,,,,,,,,5,125,0,6.93799986038357,0.244529890764881,4.11405857879817E-5,4374,0,215.0611267,215.2650299,9998.583,9998.583,0.206908892314354,223.4116,,,,,,,,,,,,,,,,,,,,,,,215.1630783
,37390073.70,225.156868,9998.583,,,0.000767885734594672,9.52707536074919E-5,,,,,,,,,5,125,0,6.8589995848015,0.244529890764881,4.08636821128971E-5,4374,0,225.0428772,225.2708588,9998.583,9998.583,0.201333062950731,234.21995,,,,,,,,,,,,,,,,,,,,,,,225.156868
,37390375.08,235.17167665,9998.583,,,0.000749878283720357,9.07155931080439E-5,,,,,,,,,5,125,0,7.04600005410612,0.244529890764881,4.06746885220876E-5,4374,0,235.0437012,235.2996521,9998.583,9998.583,0.207649287312874,243.24775,,,,,,,,,,,,,,,,,,,,,,,235.17167665
,37390677.32,245.16747285,9998.583,,,0.000703324048842498,9.52805367584608E-5,,,,,,,,,5,125,0,6.96900011971593,0.244529890764881,4.04687673723874E-5,4374,0,245.043808,245.2911377,9998.583,9998.583,0.208332790299911,253.73835,,,,,,,,,,,,,,,,,,,,,,,245.16747285
,37390981.34,255.15994265,9998.583,,,0.000688784757437618,0.00010067658439518,,,,,,,,,5,125,0,6.92199964541942,0.244529890764881,4.02132629138106E-5,4374,0,255.034256,255.2856293,9998.583,9998.583,0.197139859277385,264.5612,,,,,,,,,,,,,,,,,,,,,,,255.15994265
,37391285.00,265.1682434,9998.583,,,0.000672232365758974,0.00011032706563982,,,,,,,,,5,125,0,7.01600059401244,0.244529890764881,4.01239589732959E-5,4374,0,265.0420837,265.2944031,9998.583,9998.583,0.18773380679409,274.99115,,,,,,,,,,,,,,,,,,,,,,,265.1682434
,37391589.46,275.18467715,9998.583,,,0.000646017559872019,0.000112929024089995,,,,,,,,,5,125,0,6.95299990475178,0.244529890764881,3.9880152449251E-5,4374,0,275.0673218,275.3020325,9998.583,9998.583,0.18128862927359,285.3586,,,,,,,,,,,,,,,,,,,,,,,275.18467715
,37391892.39,285.14112855,9998.583,,,0.000627251694387578,0.000121214610820927,,,,,,,,,5,125,0,6.64100011344999,0.244529890764881,3.98744128041136E-5,4374,0,285.0256653,285.2565918,9998.583,9998.583,0.169910427173368,296.2044,,,,,,,,,,,,,,,,,,,,,,,285.14112855
,37392198.31,295.1950073,9998.583,,,0.000606770077062706,0.000124157263027674,,,,,,,,,5,125,0,7.01499979477376,0.244529890764881,3.96627393120808E-5,4374,0,295.0566711,295.3333435,9998.583,9998.583,0.160823194479222,306.79175,,,,,,,,,,,,,,,,,,,,,,,295.1950073
,37392886.94,299.6933289,9998.583,,,0.000596878949623766,0.000125378109768627,,,,,,,,,5,125,0,6.18799952790141,0.244529890764881,4.06035422676209E-5,4370,0,299.687439,299.6992188,9998.583,9998.583,0.151829433900139,300.5329,,,,,,,,,,,,,,,,,,,,,,,299.6933289
,37393373.28,289.83906555,9998.583,,,0.0006197519326682,0.000120495562302138,,,,,,,,,5,125,0,6.73500043340027,0.244529890764881,4.88613523971599E-5,4374,0,289.7184143,289.9597168,9998.583,9998.583,0.172585241024388,274.2167,,,,,,,,,,,,,,,,,,,,,,,289.83906555
,37393727.81,279.7145233,9998.583,,,0.000638906689960183,0.00011414642056739,,,,,,,,,5,125,0,6.6560001578182,0.244529890764881,4.99389367466706E-5,4374,0,279.504425,279.9246216,9998.583,9998.583,0.181520512856613,261.60175,,,,,,,,,,,,,,,,,,,,,,,279.7145233
,37394070.15,269.7130432,9998.583,,,0.000657034909086909,0.000108446509273096,,,,,,,,,5,125,0,6.2969998922199,0.244529890764881,4.88927713890334E-5,4374,0,269.4727173,269.9533691,9998.583,9998.583,0.206258740716018,258.22085,,,,,,,,,,,,,,,,,,,,,,,269.7130432
,37394412.45,259.723587,9998.583,,,0.000686087702080891,0.000104379193727032,,,,,,,,,5,125,0,7.12499970104545,0.244529890764881,4.62518354001583E-5,4374,0,259.5158691,259.9313049,9998.583,9998.583,0.205346696065728,255.90505,,,,,,,,,,,,,,,,,,,,,,,259.723587
,37394775.31,249.9693909,9998.583,,,0.00071405756117924,0.000100221938540521,,,,,,,,,5,125,0,6.84299999848008,0.244529890764881,4.40349150220716E-5,4374,0,249.9507599,249.9880219,9998.583,9998.583,0.224597033190683,255.7887,,,,,,,,,,,,,,,,,,,,,,,249.9693909
,37395281.61,239.6713028,9998.583,,,0.000724490341048348,9.64981173972415E-5,,,,,,,,,5,125,0,7.14099991600961,0.244529890764881,4.88796601747245E-5,4374,0,239.4721985,239.8704071,9998.583,9998.583,0.235321355520893,222.5608,,,,,,,,,,,,,,,,,,,,,,,239.6713028
,37395615.73,229.6530609,9998.583,,,0.000756398226126629,9.17345196865898E-5,,,,,,,,,5,125,0,6.90700022969395,0.244529890764881,4.89564665202228E-5,4374,0,229.4063263,229.8997955,9998.583,9998.583,0.242157046107641,219.53585,,,,,,,,,,,,,,,,,,,,,,,229.6530609
,37395955.10,219.77796175,9998.583,,,0.000791783410858522,8.7210771976827E-5,,,,,,,,,5,125,0,6.82799995411187,0.244529890764881,4.57757830203312E-5,4374,0,219.6564789,219.8994446,9998.583,9998.583,0.252672258491687,220.9275,,,,,,,,,,,,,,,,,,,,,,,219.77796175
,37396431.96,209.6532669,9998.583,,,0.00082237232907052,8.38160856861432E-5,,,,,,,,,5,125,0,6.86000038404018,0.244529890764881,4.90657785908555E-5,4374,0,209.4044952,209.9020386,9998.583,9998.583,0.254122512981008,194.0413,,,,,,,,,,,,,,,,,,,,,,,209.6532669
,37396752.40,199.7340393,9998.583,,,0.00084985099490756,7.98860947262554E-5,,,,,,,,,5,125,0,6.90600005909801,0.244529890764881,4.79209980859968E-5,4374,0,199.5322876,199.935791,9998.583,9998.583,0.270048491867017,197.43215,,,,,,,,,,,,,,,,,,,,,,,199.7340393
,37397245.81,189.69390865,9998.583,,,0.000878013274864481,7.68974274941845E-5,,,,,,,,,5,125,0,6.73499980475754,0.244529890764881,4.94992161089778E-5,4374,0,189.4849548,189.9028625,9998.583,9998.583,0.268227644969787,176.1081,,,,,,,,,,,,,,,,,,,,,,,189.69390865
,37397558.98,179.7159729,9998.583,,,0.000931863004929223,7.5358110875917E-5,,,,,,,,,5,125,0,6.51600016281009,0.244529890764881,4.89160609960526E-5,4374,0,179.5228119,179.9091339,9998.583,9998.583,0.263819685850798,177.33885,,,,,,,,,,,,,,,,,,,,,,,179.7159729
,37398029.96,169.64588165,9998.583,,,0.000976858415053422,6.86104512463514E-5,,,,,,,,,5,125,0,6.75000047776848,0.244529890764881,5.08262163639278E-5,4374,0,169.4285126,169.8632507,9998.583,9998.583,0.259976402429136,157.49045,,,,,,,,,,,,,,,,,,,,,,,169.64588165
,37398335.70,159.86560825,9998.583,,,0.00100453359901986,6.72800380822575E-5,,,,,,,,,5,125,0,6.96900011971593,0.244529890764881,4.72586478817258E-5,4374,0,159.7938538,159.9373627,9998.583,9998.583,0.263396335576792,163.9732,,,,,,,,,,,,,,,,,,,,,,,159.86560825
,37398776.06,149.6251526,9998.583,,,0.00104994788656147,6.39816513411263E-5,,,,,,,,,5,125,0,6.67199974413961,0.244529890764881,5.20391673802751E-5,4374,0,149.3939362,149.856369,9998.583,9998.583,0.260449145334762,141.66505,,,,,,,,,,,,,,,,,,,,,,,149.6251526
,37399193.66,139.6350784,9998.583,,,0.00110347328399098,5.90711872903744E-5,,,,,,,,,5,125,0,7.0159999653697,0.244529890764881,5.2589029547285E-5,4374,0,139.4263,139.8438568,9998.583,9998.583,0.258973917793725,130.15515,,,,,,,,,,,,,,,,,,,,,,,139.6350784
,37399586.53,129.73414615,9998.583,,,0.00114926676874862,6.06595197223822E-5,,,,,,,,,5,125,0,6.48499990347773,0.244529890764881,5.25252813042601E-5,4374,0,129.5279236,129.9403687,9998.583,9998.583,0.255302018216495,121.79385,,,,,,,,,,,,,,,,,,,,,,,129.73414615
,37399966.50,119.7596588,9998.583,,,0.00120186750512627,6.03757864871445E-5,,,,,,,,,5,125,0,6.45399964414537,0.244529890764881,5.38172446540096E-5,4374,0,119.5731735,119.9461441,9998.583,9998.583,0.251775573940054,112.61045,,,,,,,,,,,,,,,,,,,,,,,119.7596588
,37400322.74,109.6621399,9998.583,,,0.0012592541097569,5.84809125577619E-5,,,,,,,,,5,125,0,6.70400017406791,0.244529890764881,5.36793218994658E-5,4374,0,109.4863129,109.8379669,9998.583,9998.583,0.249188123445792,102.9119,,,,,,,,,,,,,,,,,,,,,,,109.6621399
,37400644.73,99.8150787,9998.583,,,0.00132064654671954,5.85909857638864E-5,,,,,,,,,5,125,0,6.79700032342225,0.244529890764881,5.1334957985587E-5,4374,0,99.7157974,99.91436,9998.583,9998.583,0.243840405889703,99.89415,,,,,,,,,,,,,,,,,,,,,,,99.8150787
,37401013.46,89.84928895,9998.583,,,0.00138960654305795,5.66229311119772E-5,,,,,,,,,5,125,0,6.8910000147298,0.244529890764881,5.41154217757891E-5,4374,0,89.727623,89.9709549,9998.583,9998.583,0.238471789352696,86.6279,,,,,,,,,,,,,,,,,,,,,,,89.84928895
,37401295.10,79.7344818,9998.583,,,0.00148099001016523,5.62526402242109E-5,,,,,,,,,5,125,0,7.04700022470206,0.244529890764881,5.28084459426341E-5,4374,0,79.5987625,79.8702011,9998.583,9998.583,0.232193921841329,78.16595,,,,,,,,,,,,,,,,,,,,,,,79.7344818
,37401620.58,69.9039612,9998.583,,,0.00155006099241148,5.31815608195816E-5,,,,,,,,,5,125,0,6.90699960105121,0.244529890764881,5.19156807271359E-5,4374,0,69.8333817,69.9745407,9998.583,9998.583,0.229293235222157,68.6383,,,,,,,,,,,,,,,,,,,,,,,69.9039612
,37401919.47,59.88344575,9998.583,,,0.00165106258922265,5.2654667295017E-5,,,,,,,,,5,125,0,6.43800005782396,0.244529890764881,5.18459865084483E-5,4370,0,59.805481,59.9614105,9998.583,9998.583,0.225794038833498,58.6233,,,,,,,,,,,,,,,,,,,,,,,59.88344575
,37403141.75,50.0519314,9998.583,,,0.00174136146905689,5.40414102240812E-5,,,,,,,,,5,125,0,6.68799995910376,0.244529890764881,4.84638903638519E-5,4370,0,50.0436287,50.0602341,9998.583,9998.583,0.222503670075425,49.88255,,,,,,,,,,,,,,,,,,,,,,,50.0519314
,37403388.49,47.94446755,9998.583,,,0.00176358288624754,5.42827242725124E-5,,,,,,,,,5,125,0,7.09400007035583,0.244529890764881,4.94856180623066E-5,4370,0,47.9053345,47.9836006,9998.583,9998.583,0.224882484592105,47.5283,,,,,,,,,,,,,,,,,,,,,,,47.94446755
,37403623.75,45.9472313,9998.583,,,0.00177501538100574,5.57243533443274E-5,,,,,,,,,5,125,0,6.81199973914772,0.244529890764881,4.96475474059302E-5,4370,0,45.9170876,45.977375,9998.583,9998.583,0.218649219976228,45.6442,,,,,,,,,,,,,,,,,,,,,,,45.9472313
,37403858.31,43.98306655,9998.583,,,0.00181660818825034,5.60537930740841E-5,,,,,,,,,5,125,0,6.81199973914772,0.244529890764881,4.98835371624673E-5,4370,0,43.9703407,43.9957924,9998.583,9998.583,0.219599670136988,43.79645,,,,,,,,,,,,,,,,,,,,,,,43.98306655
,37404112.84,41.94532395,9998.583,,,0.00184002145966816,5.41180322610898E-5,,,,,,,,,5,125,0,7.20300043467432,0.244529890764881,4.99543740294904E-5,4370,0,41.9127922,41.9778557,9998.583,9998.583,0.219347144168178,41.6034,,,,,,,,,,,,,,,,,,,,,,,41.94532395
,37404344.60,39.94961545,9998.583,,,0.00186269948518002,5.68157603480866E-5,,,,,,,,,5,125,0,6.43699988722801,0.244529890764881,5.00327164737232E-5,4370,0,39.9177818,39.9814491,9998.583,9998.583,0.218504314379733,39.65255,,,,,,,,,,,,,,,,,,,,,,,39.94961545
,37404574.82,37.99595835,9998.583,,,0.00188287289417892,5.46952647112201E-5,,,,,,,,,5,125,0,6.62499989848584,0.244529890764881,4.99630469991355E-5,4370,0,37.994648,37.9972687,9998.583,9998.583,0.222946497225035,37.90445,,,,,,,,,,,,,,,,,,,,,,,37.99595835
,37404820.75,35.9335613,9998.583,,,0.00190910363645627,5.44473446918517E-5,,,,,,,,,5,125,0,7.15599996037781,0.244529890764881,5.01527374200856E-5,4370,0,35.9017715,35.9653511,9998.583,9998.583,0.225102376628748,35.7024,,,,,,,,,,,,,,,,,,,,,,,35.9335613
,37405065.95,33.9221821,9998.583,,,0.00191927198389085,5.43084575416106E-5,,,,,,,,,5,125,0,6.81200036779046,0.244529890764881,5.01869307413373E-5,4370,0,33.8677559,33.9766083,9998.583,9998.583,0.224031324484624,33.6428,,,,,,,,,,,,,,,,,,,,,,,33.9221821
,37405307.42,31.88755895,9998.583,,,0.00195198625396222,5.30730082424737E-5,,,,,,,,,5,125,0,7.07799985539168,0.244529890764881,5.0481632697171E-5,4370,0,31.8191891,31.9559288,9998.583,9998.583,0.225406582676497,31.6005,,,,,,,,,,,,,,,,,,,,,,,31.88755895
,37405543.38,29.90978335,9998.583,,,0.00197423817240777,5.33746299311635E-5,,,,,,,,,5,125,0,6.74999984912574,0.244529890764881,5.0457204097555E-5,4370,0,29.8405571,29.9790096,9998.583,9998.583,0.225245733514974,29.65475,,,,,,,,,,,,,,,,,,,,,,,29.90978335
,37405775.46,27.95338915,9998.583,,,0.00199506502948393,5.37760898923412E-5,,,,,,,,,5,125,0,6.48399973288178,0.244529890764881,5.03864849314048E-5,4370,0,27.9311008,27.9756775,9998.583,9998.583,0.225068547427803,27.81185,,,,,,,,,,,,,,,,,,,,,,,27.95338915
,37406021.03,25.9512434,9998.583,,,0.00201819765238629,5.20888853292201E-5,,,,,,,,,5,125,0,6.63999994285405,0.244529890764881,5.03276723356406E-5,4370,0,25.9281044,25.9743824,9998.583,9998.583,0.225215768167846,25.79845,,,,,,,,,,,,,,,,,,,,,,,25.9512434
,37406256.72,23.9743824,9998.583,,,0.00204768941767079,5.20658193077546E-5,,,,,,,,,5,125,0,6.67200037278235,0.244529890764881,5.04047165644225E-5,4370,0,23.9541359,23.9946289,9998.583,9998.583,0.225872611635487,23.86215,,,,,,,,,,,,,,,,,,,,,,,23.9743824
,37406496.13,21.9757395,9998.583,,,0.00207119708859249,5.24277423380229E-5,,,,,,,,,5,125,0,7.26599986664951,0.244529890764881,5.04169452838489E-5,4370,0,21.9642849,21.9871941,9998.583,9998.583,0.224627788521012,21.8882,,,,,,,,,,,,,,,,,,,,,,,21.9757395
,37406736.92,19.97843265,9998.583,,,0.00210015730382647,5.05637741976197E-5,,,,,,,,,5,125,0,6.93699968978763,0.244529890764881,5.06569501233822E-5,4370,0,19.9674873,19.989378,9998.583,9998.583,0.224704767220447,19.8943,,,,,,,,,,,,,,,,,,,,,,,19.97843265
,37406978.67,17.9623203,9998.583,,,0.00211441452922561,5.19564248820244E-5,,,,,,,,,5,125,0,6.32800015155226,0.244529890764881,5.07066821773408E-5,4370,0,17.9452381,17.9794025,9998.583,9998.583,0.221404295298381,17.8703,,,,,,,,,,,,,,,,,,,,,,,17.9623203
,37407216.33,15.96693515,9998.583,,,0.00211791249778291,5.3243128073306E-5,,,,,,,,,5,125,0,6.99999975040555,0.244529890764881,5.06438842681753E-5,4370,0,15.9490137,15.9848566,9998.583,9998.583,0.218436146023257,15.89045,,,,,,,,,,,,,,,,,,,,,,,15.96693515
,37407456.17,13.9790778,9998.583,,,0.00212333196489138,5.21709055287345E-5,,,,,,,,,5,125,0,6.5310002071783,0.244529890764881,5.0425362894537E-5,4370,0,13.9703436,13.987812,9998.583,9998.583,0.220145982163759,13.90195,,,,,,,,,,,,,,,,,,,,,,,13.9790778
,37407699.19,11.97188185,9998.583,,,0.00211895223950615,5.23867725139032E-5,,,,,,,,,5,125,0,6.60899968352169,0.244529890764881,5.05425760997006E-5,4370,0,11.9694872,11.9742765,9998.583,9998.583,0.218064469672048,11.9109,,,,,,,,,,,,,,,,,,,,,,,11.97188185
,37407974.00,9.9821625,9998.583,,,0.00215988562771215,5.26302584383726E-5,,,,,,,,,5,125,0,6.87499979976565,0.244529890764881,5.05166439746644E-5,4370,0,9.9775944,9.9867306,9998.583,9998.583,0.210607539370221,9.92085,,,,,,,,,,,,,,,,,,,,,,,9.9821625
,37408249.00,7.97087715,9998.583,,,0.00218986814304157,5.37839248113394E-5,,,,,,,,,5,125,0,6.73400026280433,0.244529890764881,5.06592706623635E-5,4370,0,7.9472208,7.9945335,9998.583,9998.583,0.210592116531277,7.95825,,,,,,,,,,,,,,,,,,,,,,,7.97087715
,37408538.22,5.9728751,9998.583,,,0.00228100167735045,5.44195961984515E-5,,,,,,,,,5,125,0,6.43800005782396,0.244529890764881,5.07666296600133E-5,4370,0,5.9637794,5.9819708,9998.583,9998.583,0.205129292812457,5.96095,,,,,,,,,,,,,,,,,,,,,,,5.9728751
,37408836.70,3.97048485,9998.583,,,0.00238928519732521,5.21396863393294E-5,,,,,,,,,5,125,0,6.81199973914772,0.244529890764881,5.12761094765576E-5,4370,0,3.9501786,3.9907911,9998.583,9998.583,0.207347929153939,3.967,,,,,,,,,,,,,,,,,,,,,,,3.97048485
,37409122.27,1.996455,9998.583,,,0.00257917120528824,4.26509544333946E-5,,,,,,,,,5,125,0,6.59400026779622,0.244529890764881,5.20134462317533E-5,4370,0,1.9869791,2.0059309,9998.583,9998.583,0.22511480219713,1.99935,,,,,,,,,,,,,,,,,,,,,,,1.996455
,37418111.34,1.80373765,10.012,1000,10.0020797255318,,0.164078866197445,,,,,,,,,,125,1,0,-0.0266756915230171,0.000220155574339652,4374,0,1.8020202,1.8054551,10.012,10.012,,1.7787,,,,,,,,,,,,,,,,,,,,,,,1.80373765
,37418180.85,1.786149,10.012,1000,10.0020797255318,,0.151194191933325,,,,,,,,,,125,1,0,-0.0351832982504319,0.000219945980883563,4373,0,1.7850859,1.7872121,10.012,10.012,,1.77795,,,,,,,,,,,,,,,,,,,,,,,1.786149
,37418390.35,2.3913087,10.012,100,5.00030446829275,,7.69762119109759E-8,1.44415982551282E-6,-9.34359430278682E-8,1.44717928297593E-6,-3.70182990536233,1.51674734564336E-8,-8.56370424114984E-12,1.51674758740091E-8,-0.0323497555006043,800,25,5,13.4965986394558,-0.0351832982504319,9.05434093823219E-5,4370,0,2.3262033,2.4470484,10.012,10.012,,2.3929,,,,,,,,,,,,,,,,,,,,,,,2.3913087
,37418512.81,3.3871784875,10.012,100,5.00030446829275,,2.4139164641111E-8,1.24729929024482E-6,1.97989647843575E-8,1.24745641945992E-6,0.909406320740856,1.51674441047193E-8,-7.25967220119322E-12,1.51674458420864E-8,-0.0274237731249514,800,25,5,13.4965986394558,-0.0351832982504319,9.0162768393103E-5,4370,0,3.3229907,3.4463322,10.012,10.012,,3.3955625,,,,,,,,,,,,,,,,,,,,,,,3.3871784875
,37418635.66,4.3890564625,10.012,100,5.00030446829275,,4.11634026655763E-8,1.40330670039673E-6,7.91850235112533E-8,1.40553902945697E-6,3.22963006097289,1.51650255798723E-8,-7.96418125554719E-12,1.51650276711374E-8,-0.0300898886629852,800,25,5,13.4965986394558,-0.0351832982504319,9.01919990513468E-5,4370,0,4.3212624,4.4541616,10.012,10.012,,4.3981375,,,,,,,,,,,,,,,,,,,,,,,4.3890564625
,37418756.66,5.3828633375,10.012,100,5.00030446829275,,2.94904532297472E-8,1.20256198736608E-6,1.44851675857883E-7,1.21125444950956E-6,6.86833401024425,1.51638766182913E-8,-7.95853557704359E-12,1.51638787067508E-8,-0.0300708367180391,800,25,5,13.4965986394558,-0.0351832982504319,9.01756170340893E-5,4370,0,5.3138161,5.44908,10.012,10.012,,5.3996375,,,,,,,,,,,,,,,,,,,,,,,5.3828633375
,37418877.65,6.382201475,10.012,100,5.00030446829275,,6.54470242842916E-8,1.25711778014505E-6,-3.06608554475611E-8,1.25749163067338E-6,-1.39715580060039,1.5163647910185E-8,-7.38638928997453E-12,1.51636497091829E-8,-0.0279094384932819,800,25,5,13.4965986394558,-0.0351832982504319,9.03066731721495E-5,4370,0,6.3099432,6.4530649,10.012,10.012,,6.4006875,,,,,,,,,,,,,,,,,,,,,,,6.382201475
,37418998.82,7.3850594,10.012,100,5.00030446829275,,3.62599702136353E-8,1.23481552817501E-6,-1.91385248800088E-8,1.23496383418977E-6,-0.887961710626996,1.51643270189585E-8,-8.41383880984317E-12,1.51643293531432E-8,-0.0317902273694699,800,25,5,13.4965986394558,-0.0351832982504319,9.03930802827823E-5,4370,0,7.3130875,7.4547453,10.012,10.012,,7.4007875,,,,,,,,,,,,,,,,,,,,,,,7.3850594
,37419118.03,8.377651925,10.012,100,5.00030446829275,,5.59901228952419E-8,1.2706990790518E-6,4.41581552588804E-8,1.27146611916282E-6,1.99028883811415,1.51644519313455E-8,-7.86301318950863E-12,1.5164453969895E-8,-0.0297087841801726,800,25,5,13.4965986394558,-0.0351832982504319,9.02491755037358E-5,4370,0,8.3068409,8.4469728,10.012,10.012,,8.386875,,,,,,,,,,,,,,,,,,,,,,,8.377651925
,37419209.36,9.141868925,10.012,100,5.00030446829275,,2.85094428241463E-8,1.20511947061987E-6,-2.63212598881206E-8,1.20540688034755E-6,-1.25120986076399,1.51644311271899E-8,-7.68049890496698E-12,1.51644330722038E-8,-0.0290192312846784,800,25,5,13.4965986394558,-0.0351832982504319,9.04409414704562E-5,4370,0,9.0592327,9.1698942,10.012,10.012,,9.1370875,,,,,,,,,,,,,,,,,,,,,,,9.141868925
,37419327.23,10.11000275,10.012,100,5.00030446829275,,3.76055957241175E-8,1.22687194683567E-6,7.02061222928411E-8,1.22887903128817E-6,3.27510338765943,1.51647482639226E-8,-7.4071401919701E-12,1.51647500729115E-8,-0.0279858148730909,800,25,5,13.4965986394558,-0.0351832982504319,9.04865541459575E-5,4370,0,10.0532494,10.1809978,10.012,10.012,,10.117975,,,,,,,,,,,,,,,,,,,,,,,10.11000275
,37419448.97,11.123154775,10.012,100,5.00030446829275,,3.8570924969161E-8,1.22911323161062E-6,1.18955544752504E-8,1.2291707938023E-6,0.554500407339021,1.51637056457149E-8,-7.60456915965741E-12,1.51637075525532E-8,-0.0287337206034408,800,25,5,13.4965986394558,-0.0351832982504319,9.0607973803278E-5,4370,0,11.0503483,11.1921024,10.012,10.012,,11.13125,,,,,,,,,,,,,,,,,,,,,,,11.123154775
,37419570.31,12.12507725,10.012,100,5.00030446829275,,2.57349395860053E-8,1.25155714154611E-6,-1.10681839662205E-8,1.25160608150144E-6,-0.506683774733176,1.51647767989987E-8,-8.59952969320254E-12,1.51647792372775E-8,-0.0324908642530204,800,25,5,13.4965986394558,-0.0351832982504319,9.05167484522753E-5,4370,0,12.0536547,12.1930809,10.012,10.012,,12.1482125,,,,,,,,,,,,,,,,,,,,,,,12.12507725
,37419688.04,13.1061882875,10.012,100,5.00030446829275,,4.79503837142234E-8,1.14976792951203E-6,8.01647625235567E-8,1.15255918758424E-6,3.98835395959386,1.51652802025593E-8,-8.64509690135904E-12,1.51652826666646E-8,-0.0326619426518278,800,25,5,13.4965986394558,-0.0351832982504319,9.05212454766205E-5,4370,0,13.0384331,13.1742668,10.012,10.012,,13.1198875,,,,,,,,,,,,,,,,,,,,,,,13.1061882875
,37419809.58,14.113057,10.012,100,5.00030446829275,,2.37274216417223E-8,1.396593970391E-6,-5.13486185802235E-8,1.39753761980227E-6,-2.10564742414147,1.51645382073971E-8,-6.45179194353661E-12,1.51645395798628E-8,-0.0243766358923381,800,25,5,13.4965986394558,-0.0351832982504319,9.06625805274697E-5,4370,0,14.0418777,14.1822128,10.012,10.012,,14.13495,,,,,,,,,,,,,,,,,,,,,,,14.113057
,37419929.70,15.1065580875,10.012,100,5.00030446829275,,2.86659102076157E-8,1.14352200065319E-6,4.15298976120584E-8,1.14427588385561E-6,2.07992721631608,1.5164395746112E-8,-7.62848096746539E-12,1.51643976648735E-8,-0.0288227591775012,800,25,5,13.4965986394558,-0.0351832982504319,9.0949105221464E-5,4370,0,15.0348263,15.1750546,10.012,10.012,,15.1391375,,,,,,,,,,,,,,,,,,,,,,,15.1065580875
,37420049.97,16.1056809375,10.012,100,5.00030446829275,,4.15632435497109E-8,1.33114111857207E-6,2.76683465089592E-8,1.33142863682281E-6,1.19074620996405,1.51644908035783E-8,-9.0273972458825E-12,1.51644934905757E-8,-0.0341080823469611,800,25,5,13.4965986394558,-0.0351832982504319,9.07130114433409E-5,4370,0,16.033041,16.1732159,10.012,10.012,,16.13865,,,,,,,,,,,,,,,,,,,,,,,16.1056809375
,37420170.02,17.1050210125,10.012,100,5.00029564519686,,2.40028215166787E-8,1.22080202885793E-6,-1.95046119417224E-8,1.22095783037361E-6,-0.915330124030959,1.51664942180841E-8,-9.40547060044987E-12,1.51664971344755E-8,-0.0355318567961831,800,25,5,13.4965986394558,-0.0351832982504319,9.0573282472615E-5,4370,0,17.0325928,17.1763897,10.012,10.012,,17.137025,,,,,,,,,,,,,,,,,,,,,,,17.1050210125
,37420289.78,18.1026957,10.012,100,5.00024539844845,,4.39042405909086E-8,1.14015214458345E-6,3.50094485398874E-8,1.14068951704016E-6,1.75876841352764,1.51686020923845E-8,-8.89328382882379E-12,1.51686046994307E-8,-0.0335922564199223,800,25,5,13.4965986394558,-0.0351832982504319,9.07656908713847E-5,4370,0,18.0340862,18.1729527,10.012,10.012,,18.1309,,,,,,,,,,,,,,,,,,,,,,,18.1026957
,37420409.77,19.097537525,10.012,100,5.00015584999215,,3.43321590797775E-8,1.28411745762353E-6,-5.8208740089669E-8,1.28543607479966E-6,-2.59542739858352,1.51699979208524E-8,-6.39928184980445E-12,1.51699992705825E-8,-0.0241695366125327,800,25,5,13.4965986394558,-0.0351832982504319,9.08565950063627E-5,4370,0,19.0295753,19.1621895,10.012,10.012,,19.1336375,,,,,,,,,,,,,,,,,,,,,,,19.097537525
,37420529.21,20.0197599,10.012,100,5.00002462891819,,5.62417338641927E-8,1.0820052253846E-6,-5.61400057488204E-8,1.08346066287848E-6,-2.97013687724279,1.51733994167889E-8,-9.73266018640822E-12,1.51734025381944E-8,-0.0367511762079289,800,25,5,13.4965986394558,-0.0351832982504319,9.07923518014313E-5,4373,0,19.9976654,20.0312233,10.012,10.012,,20.0096625,,,,,,,,,,,,,,,,,,,,,,,20.0197599
,37423295.02,2.3860571125,10.04,300,4.99985787232671,,1.44571397988881E-8,1.40713544817498E-6,-3.76067878920883E-9,1.4071404735191E-6,-0.153127056812309,1.51622440637643E-8,-8.26978837739243E-11,1.51624695874102E-8,-0.31249943682468,1200,25,5,13.4965986394558,-0.0351832982504319,0.000115042234366908,4370,0,2.3249261,2.4492593,10.04,10.04,,2.3914125,,,,,,,,,,,,,,,,,,,,,,,2.3860571125
,37423419.85,3.3949815,10.04,300,4.99985787232671,,1.38586743837071E-8,1.36292531175297E-6,-2.36914915297089E-8,1.36313120872051E-6,-0.995862185063913,1.51622707423934E-8,-8.26079552757448E-11,1.51624957754294E-8,-0.312159071764881,1200,25,5,13.4965986394558,-0.0351832982504319,0.000114809031533007,4370,0,3.3359158,3.4554203,10.04,10.04,,3.4064625,,,,,,,,,,,,,,,,,,,,,,,3.3949815
,37423541.12,4.3862364125,10.04,300,4.99985787232671,,1.34296592811639E-8,1.31399773158707E-6,4.99095953634786E-8,1.31494524841353E-6,2.17522077624282,1.51579199693256E-8,-8.23656769006233E-11,1.51581437485336E-8,-0.311332902282288,1200,25,5,13.4965986394558,-0.0351832982504319,0.000114570903386728,4370,0,4.3193917,4.4546332,10.04,10.04,,4.397125,,,,,,,,,,,,,,,,,,,,,,,4.3862364125
,37423662.08,5.3780509875,10.04,300,4.99985787232671,,2.3257469995901E-8,1.3012013881105E-6,-1.14735808045314E-8,1.30125197232403E-6,-0.505202903385793,1.51576873339986E-8,-8.24383456888616E-11,1.5157911511686E-8,-0.311612358991965,1200,25,5,13.4965986394558,-0.0351832982504319,0.000114843294575637,4370,0,5.3153262,5.4433618,10.04,10.04,,5.3975625,,,,,,,,,,,,,,,,,,,,,,,5.3780509875
,37423782.17,6.378861075,10.04,300,4.99985787232671,,1.9051220869201E-8,1.30702686278391E-6,-7.87147479911755E-9,1.30705056526298E-6,-0.345055518697052,1.51580977343447E-8,-8.27580711277137E-11,1.51583236481572E-8,-0.31281241003694,1200,25,5,13.4965986394558,-0.0351832982504319,0.000114796611180054,4370,0,6.3090258,6.450037,10.04,10.04,,6.3857125,,,,,,,,,,,,,,,,,,,,,,,6.378861075
,37423903.39,7.3843764125,10.04,300,4.99985787232671,,1.96784117732024E-8,1.23834760195295E-6,-3.08509324037667E-8,1.2387318367156E-6,-1.42711356435331,1.51578778149819E-8,-8.3148348194093E-11,1.51581058678757E-8,-0.314292125830093,1200,25,5,13.4965986394558,-0.0351832982504319,0.000114521650262947,4370,0,7.3151832,7.4524531,10.04,10.04,,7.3852875,,,,,,,,,,,,,,,,,,,,,,,7.3843764125
,37424023.89,8.3884989125,10.04,300,4.99985787232671,,1.43674021642991E-8,1.21673307193092E-6,-6.84432014633705E-9,1.21675232198206E-6,-0.322294619045806,1.51575216984465E-8,-8.25486075510573E-11,1.51577464786651E-8,-0.312032544126453,1200,25,5,13.4965986394558,-0.0351832982504319,0.000114752069224635,4370,0,8.3069553,8.4628439,10.04,10.04,,8.39395,,,,,,,,,,,,,,,,,,,,,,,8.3884989125
,37424143.24,9.3737507,10.04,300,4.99985787232671,,1.84800590405965E-8,1.25538201516933E-6,1.04842780438383E-8,1.25542579394272E-6,0.47849253111858,1.51571916123169E-8,-8.29756578892354E-11,1.51574187291997E-8,-0.313653586384135,1200,25,5,13.4965986394558,-0.0351832982504319,0.00011503795148658,4370,0,9.3018503,9.429225,10.04,10.04,,9.381375,,,,,,,,,,,,,,,,,,,,,,,9.3737507
,37424263.87,10.374333375,10.04,300,4.99985787232671,,1.48215749879441E-8,1.22456222188988E-6,3.17301885266144E-8,1.22497324058275E-6,1.48428486951218,1.51575569656874E-8,-8.28980119723559E-11,1.5157783652251E-8,-0.313352532443787,1200,25,5,13.4965986394558,-0.0351832982504319,0.000115028529149856,4370,0,10.3000669,10.4378481,10.04,10.04,,10.3841125,,,,,,,,,,,,,,,,,,,,,,,10.374333375
,37424384.04,11.3655028375,10.04,300,4.99985787232671,,2.4521297806753E-8,1.21959883834431E-6,2.5883922697252E-8,1.21987347866284E-6,1.21582349327654,1.51579710600718E-8,-8.28954719008923E-11,1.51581977265517E-8,-0.31333437130877,1200,25,5,13.4965986394558,-0.0351832982504319,0.000114990197370914,4370,0,11.3019714,11.4366894,10.04,10.04,,11.3861875,,,,,,,,,,,,,,,,,,,,,,,11.3655028375
,37424504.74,12.3660678875,10.04,300,4.99985787232671,,1.30260206563175E-8,1.2506560521162E-6,7.64089539396918E-9,1.250679392961E-6,0.350044770617975,1.51574059754967E-8,-8.26220321124558E-11,1.51576311574801E-8,-0.312312466773903,1200,25,5,13.4965986394558,-0.0351832982504319,0.000115356383639023,4370,0,12.2929859,12.4309845,10.04,10.04,,12.3920625,,,,,,,,,,,,,,,,,,,,,,,12.3660678875
,37424624.76,13.3680971625,10.04,300,4.99985787232671,,1.1629520515497E-8,1.26911316732508E-6,-1.4914306459253E-8,1.26920079893414E-6,-0.673294944814529,1.51577887215238E-8,-8.32314409877652E-11,1.5158017231786E-8,-0.314608050790298,1200,25,5,13.4965986394558,-0.0351832982504319,0.000115047159679287,4370,0,13.2931938,13.4356298,10.04,10.04,,13.3846125,,,,,,,,,,,,,,,,,,,,,,,13.3680971625
,37424745.38,14.3630588125,10.04,300,4.99985787232671,,1.42695381242054E-8,1.21325185007534E-6,3.22403060351982E-8,1.21368014280719E-6,1.52218918326766,1.51585417507613E-8,-8.26370105115443E-11,1.51587669975193E-8,-0.312345679982116,1200,25,5,13.4965986394558,-0.0351832982504319,0.000115260875407692,4370,0,14.2891865,14.4341812,10.04,10.04,,14.3923,,,,,,,,,,,,,,,,,,,,,,,14.3630588125
,37424864.77,15.353317025,10.04,300,4.99985787232671,,9.96421856539267E-9,1.21787081691107E-6,-2.60296132679882E-8,1.21814895125781E-6,-1.22439911688758,1.51581885349783E-8,-8.29039857228751E-11,1.51584152447674E-8,-0.313362056046401,1200,25,5,13.4965986394558,-0.0351832982504319,0.000115252309647034,4370,0,15.2924757,15.415122,10.04,10.04,,15.3848375,,,,,,,,,,,,,,,,,,,,,,,15.353317025
,37424984.21,16.3452033875,10.04,300,4.9998611927348,,1.64078178049102E-8,1.21933662076402E-6,3.17979489195488E-8,1.21975116490689E-6,1.49382492606209,1.51583320205051E-8,-8.30476161880244E-11,1.5158559514361E-8,-0.31390197104821,1200,25,5,13.4965986394558,-0.0351832982504319,0.000115166866184475,4370,0,16.2770538,16.4163952,10.04,10.04,,16.3789875,,,,,,,,,,,,,,,,,,,,,,,16.3452033875
,37425104.92,17.3529350625,10.04,300,4.99984007397149,,1.58014095499723E-8,1.23543835908342E-6,-4.15693786434588E-8,1.23613751352167E-6,-1.92713113621483,1.51594751785178E-8,-8.26445330508415E-11,1.51597004524146E-8,-0.31235487888847,1200,25,5,13.4965986394558,-0.0351832982504319,0.000115194062474563,4370,0,17.2861652,17.4207745,10.04,10.04,,17.3820875,,,,,,,,,,,,,,,,,,,,,,,17.3529350625
,37425224.74,18.3485042875,10.04,300,4.99978037620548,,1.96145168291461E-8,1.22122164696377E-6,-8.75430399972695E-9,1.22125302409101E-6,-0.410716663602557,1.51612733931699E-8,-8.32278168863525E-11,1.51615018310174E-8,-0.314522047250193,1200,25,5,13.4965986394558,-0.0351832982504319,0.000115222543628749,4370,0,18.279995,18.4146328,10.04,10.04,,18.3789625,,,,,,,,,,,,,,,,,,,,,,,18.3485042875
,37425344.61,19.34066105,10.04,300,4.99968055922237,,1.67368185713441E-8,1.22764222205148E-6,1.41990024501503E-8,1.22772433267166E-6,0.66265775565412,1.51633277900385E-8,-8.37548695563226E-11,1.51635590989163E-8,-0.316470883175157,1200,25,5,13.4965986394558,-0.0351832982504319,0.000115257020815396,4370,0,19.2778034,19.4031029,10.04,10.04,,19.3784875,,,,,,,,,,,,,,,,,,,,,,,19.34066105
,37425437.02,20.0105276125,10.04,300,4.99957609146946,,1.55081789658202E-8,1.20264621577492E-6,3.4448333649076E-9,1.20265114941726E-6,0.164116321618155,1.51635859773024E-8,-8.39725189224479E-11,1.51638184859545E-8,-0.317287860214378,1200,25,5,13.4965986394558,-0.0351832982504319,0.000115960698053412,4373,0,19.9866409,20.0282536,10.04,10.04,,19.99735,,,,,,,,,,,,,,,,,,,,,,,20.0105276125
,37428494.43,2.3809211875,9.932,1000,4.99895523193764,,4.39018101178532E-9,1.38379282848176E-6,1.99355348344224E-8,1.38393642112153E-6,0.82537138046255,1.5185852936577E-8,-3.06610218985832E-10,1.51889479305754E-8,-1.1566742410289,666,25,5,13.4965986394558,-0.0351832982504319,0.000202780107299204,4370,0,2.3200607,2.4408934,9.932,9.932,,2.378625,,,,,,,,,,,,,,,,,,,,,,,2.3809211875
,37428620.95,3.3989184375,9.932,1000,4.99895523193764,,4.65497578431695E-9,1.34989039408764E-6,1.68549126643496E-8,1.3499956163377E-6,0.715365619684357,1.51852765952079E-8,-3.06538116758999E-10,1.51883702512809E-8,-1.15644619038824,666,25,5,13.4965986394558,-0.0351832982504319,0.000202552844550227,4370,0,3.3312407,3.4725935,9.932,9.932,,3.4081125,,,,,,,,,,,,,,,,,,,,,,,3.3989184375
,37428741.88,4.3905815625,9.932,1000,4.99895523193764,,3.07682578534545E-9,1.31593184270101E-6,1.177333819326E-9,1.31593236936759E-6,0.0512611966198552,1.5181065938167E-8,-3.06181751765054E-10,1.5184153262006E-8,-1.15542242677952,666,25,5,13.4965986394558,-0.0351832982504319,0.000202256515532886,4370,0,4.3212543,4.4548025,9.932,9.932,,4.3980375,,,,,,,,,,,,,,,,,,,,,,,4.3905815625
,37428862.29,5.3789390375,9.932,1000,4.99895523193764,,4.95418946652076E-9,1.28154205934842E-6,-7.25114516961239E-10,1.2815422644884E-6,-0.0324187542257164,1.51812293048417E-8,-3.05993463438651E-10,1.51843127999212E-8,-1.15469966258161,666,25,5,13.4965986394558,-0.0351832982504319,0.000202465257718279,4370,0,5.3106575,5.4462056,9.932,9.932,,5.393975,,,,,,,,,,,,,,,,,,,,,,,5.3789390375
,37428984.04,6.3830791,9.932,1000,4.99895523193764,,3.24363056332237E-9,1.26244637319972E-6,2.07223575894796E-9,1.26244807392866E-6,0.0940477623692786,1.51810261191463E-8,-3.06166603976177E-10,1.51841131456399E-8,-1.15536830947775,666,25,5,13.4965986394558,-0.0351832982504319,0.000202861134764884,4370,0,6.3133726,6.4528036,9.932,9.932,,6.4010125,,,,,,,,,,,,,,,,,,,,,,,6.3830791
,37429101.30,7.355317525,9.932,1000,4.99895523193764,,2.2995619618229E-9,1.24601162106835E-6,1.29667635374477E-8,1.24607908930132E-6,0.596233609896747,1.51811857226337E-8,-3.06241125958495E-10,1.51842742194787E-8,-1.15563730743031,666,25,5,13.4965986394558,-0.0351832982504319,0.000202843771736524,4370,0,7.3098063,7.4286537,9.932,9.932,,7.3666625,,,,,,,,,,,,,,,,,,,,,,,7.355317525
,37429199.36,8.1662015875,9.932,1000,4.99895523193764,,5.2942883952709E-9,1.24210146917294E-6,6.2796284790481E-9,1.24211734286878E-6,0.28966485615109,1.51811915829984E-8,-3.06345670258382E-10,1.5184282187492E-8,-1.15603126459757,666,25,5,13.4965986394558,-0.0351832982504319,0.000202905892793544,4370,0,8.1419706,8.2151775,9.932,9.932,,8.1726875,,,,,,,,,,,,,,,,,,,,,,,8.1662015875
,37429313.93,9.1269844875,9.932,1000,4.99895523193764,,2.76157533397934E-9,1.23967226693866E-6,6.4507364071112E-10,1.23967243477333E-6,0.0298143265261866,1.51812243762347E-8,-3.06321417449766E-10,1.51843144847691E-8,-1.15593727232846,666,25,5,13.4965986394558,-0.0351832982504319,0.000202592972437992,4370,0,9.0594187,9.1986446,9.932,9.932,,9.13155,,,,,,,,,,,,,,,,,,,,,,,9.1269844875
,37429434.65,10.1198973625,9.932,1000,4.99895523193764,,4.55312448637007E-9,1.22536985034725E-6,6.68918526605678E-9,1.2253881080456E-6,0.312769468787203,1.51811853681268E-8,-3.06184320002599E-10,1.518427271947E-8,-1.15542302849104,666,25,5,13.4965986394558,-0.0351832982504319,0.000202977274132357,4370,0,10.0615702,10.1857328,9.932,9.932,,10.1272,,,,,,,,,,,,,,,,,,,,,,,10.1198973625
,37429555.60,11.1250271875,9.932,1000,4.99895523193764,,3.18312323067446E-9,1.21877583948172E-6,1.45194919973542E-8,1.21886232305057E-6,0.682542460061649,1.51810197973281E-8,-3.06507466373085E-10,1.51841137019521E-8,-1.15665474015708,666,25,5,13.4965986394558,-0.0351832982504319,0.000202924027512054,4370,0,11.0503273,11.1943674,9.932,9.932,,11.1351125,,,,,,,,,,,,,,,,,,,,,,,11.1250271875
,37429675.87,12.1138495125,9.932,1000,4.99895523193764,,5.10562398194378E-9,1.2176153473084E-6,5.68186991127108E-10,1.21761547987754E-6,0.0267364519302685,1.51812362026288E-8,-3.06236575316005E-10,1.51843245974284E-8,-1.15561629812015,666,25,5,13.4965986394558,-0.0351832982504319,0.00020318601631775,4370,0,12.0464945,12.1776209,9.932,9.932,,12.141275,,,,,,,,,,,,,,,,,,,,,,,12.1138495125
,37429795.54,13.11386955,9.932,1000,4.99895523193764,,4.76153491737137E-9,1.22048793338713E-6,1.18096433364059E-9,1.22048850474731E-6,0.0554403276791971,1.51811099365544E-8,-3.061698270762E-10,1.51841970109967E-8,-1.15537409174397,666,25,5,13.4965986394558,-0.0351832982504319,0.000202976888287283,4370,0,13.0472879,13.1849833,9.932,9.932,,13.130375,,,,,,,,,,,,,,,,,,,,,,,13.11386955
,37429915.25,14.10603405,9.932,1000,4.99895523193764,,5.0151979742599E-9,1.21328182977084E-6,1.1941328189896E-8,1.21334059264949E-6,0.563896696970291,1.51810924628182E-8,-3.0643492056866E-10,1.51841848884021E-8,-1.15637551775023,666,25,5,13.4965986394558,-0.0351832982504319,0.000203116950049385,4370,0,14.0356951,14.1711054,9.932,9.932,,14.13005,,,,,,,,,,,,,,,,,,,,,,,14.10603405
,37430035.93,15.1049607,9.932,1000,4.99895523193764,,7.57548628903254E-9,1.22288297969078E-6,1.44552085821872E-8,1.22296841131427E-6,0.677238857553198,1.51815780427907E-8,-3.06308010686623E-10,1.51846678089037E-8,-1.15585977420619,666,25,5,13.4965986394558,-0.0351832982504319,0.000203061388358634,4370,0,15.0360575,15.172225,9.932,9.932,,15.13465,,,,,,,,,,,,,,,,,,,,,,,15.1049607
,37430157.42,16.1147909125,9.932,1000,4.99895523193764,,3.89366476025809E-9,1.22107219000983E-6,4.42826323797904E-9,1.22108021961323E-6,0.207784342237316,1.51818518203154E-8,-3.06596819554385E-10,1.51849473592692E-8,-1.15692844667382,666,25,5,13.4965986394558,-0.0351832982504319,0.000203111162373265,4370,0,16.041708,16.1834736,9.932,9.932,,16.1503125,,,,,,,,,,,,,,,,,,,,,,,16.1147909125
,37430275.66,17.0975985625,9.932,1000,4.99894639302974,,4.18579241089304E-9,1.22549269014898E-6,1.83781562317875E-8,1.22563048682507E-6,0.85917432922708,1.51825957676354E-8,-3.06830369259869E-10,1.51856958720673E-8,-1.15775277829005,666,25,5,13.4965986394558,-0.0351832982504319,0.000203315660262837,4370,0,17.0307865,17.1677742,9.932,9.932,,17.130725,,,,,,,,,,,,,,,,,,,,,,,17.0975985625
,37430396.20,18.100986225,9.932,1000,4.99889658694435,,5.35511640542699E-9,1.22391179692001E-6,5.40071818637839E-9,1.22392371265405E-6,0.252825694462537,1.5183691941921E-8,-3.06974898110049E-10,1.51867947433034E-8,-1.15821437603171,666,25,5,13.4965986394558,-0.0351832982504319,0.000203361575826722,4370,0,18.0300007,18.1705303,9.932,9.932,,18.13065,,,,,,,,,,,,,,,,,,,,,,,18.100986225
,37430515.74,19.09176205,9.932,1000,4.9988072119047,,5.05121583008432E-9,1.21079648499398E-6,2.70006804232481E-12,1.21079648499699E-6,0.000127769204106894,1.51852590643236E-8,-3.07213948078067E-10,1.51883663789268E-8,-1.15899647566971,666,25,5,13.4965986394558,-0.0351832982504319,0.00020312312357058,4370,0,19.0245399,19.1634083,9.932,9.932,,19.13115,,,,,,,,,,,,,,,,,,,,,,,19.09176205
,37430636.04,20.023785825,9.932,1000,4.9986769685583,,4.21500737025607E-9,1.20533050903104E-6,1.04505428228469E-8,1.20537581270172E-6,0.496757519709075,1.51865485084368E-8,-3.0771144585604E-10,1.51896656294013E-8,-1.16077428518759,666,25,5,13.4965986394558,-0.0351832982504319,0.000203003897442509,4373,0,20.0038223,20.0341301,9.932,9.932,,20.0211625,,,,,,,,,,,,,,,,,,,,,,,20.023785825
,37433589.97,1.9000415875,9.89,3000,5.00041888296292,,1.5090040382172E-9,1.40558107823527E-6,1.91528434289453E-8,1.40571156319654E-6,0.780680104486841,1.51378862300222E-8,-1.01933907538046E-9,1.51721670061891E-8,-3.85230755458588,1200,25,5,13.4965986394558,-0.0351832982504319,0.00044989366512688,4370,0,1.8195665,1.9728781,9.89,9.89,,1.877275,,,,,,,,,,,,,,,,,,,,,,,1.9000415875