File: MaterialsAutomated0-CurieWeissAnalysis/140305 DCWb1132 Na1.8IrO3.dat
[Header]
; ACMS Data File (default extension .dat)
; Copyright 1999, Quantum Design, Inc. All rights reserved.
TITLE,Na1.8IrO3
FILEOPENTIME,37290260.33,03/08/2014,4:33 pm
BYAPP,ACMS,1.0,1.1
INFO,PPMS ACMS Option Version: 1.0.9 Build 14,APPNAME
INFO,HARMONICS,1
INFO,DCWb1132,Na1.8IrO3
INFO,mass (g) =,0.0454
INFO,,
INFO,,
INFO,,
INFO,,
INFO,,
INFO,,
INFO,,
INFO,,
DATATYPE,COMMENT,1
DATATYPE,TIME,2
FIELDGROUP,AC Mag,2,3,4,5,6,8,9,10,11,12
FIELDGROUP,DC Mag,2,3,4,7,8
STARTUPGROUP,All
STARTUPAXIS,X,2,LINEAR,AUTO
TIMEMODE,MINUTES,RELATIVE
PLOT_APPEARANCE,ALL,HORZ_GRID_ON,VERT_GRID_ON,MARKERS_AND_LINES
RECORDS,ALL_RECORDS
DATATYPE,TIME,2
DATATYPE,COMMENT,1
[Data]
Comment,Time Stamp (sec),Temperature (K),Magnetic Field (Oe),Frequency (Hz),Amplitude (Oe),M-DC (emu),M-Std.Dev. (emu),M' (emu),M'' (emu),Moment (emu),Phase (deg),Calcoil' (emu),Calcoil'' (emu),Calcoil (emu),CC Phase (deg),Count,Gain,Measure Type,Elapsed (sec),Sample Center (cm),Max.Signal (V),PPMS Status (code),DSP Status (code),Min.Temperature (K),Max.Temperature (K),Min.Field (Oe),Max.Field (Oe),DC Position (cm),PPMS Temperature (K),PPMS Position,Bridge 1 Resistance (ohms),Bridge 1 Excitation (uA),Bridge 2 Resistance (ohms),Bridge 2 Excitation (uA),Bridge 3 Resistance (ohms),Bridge 3 Excitation (uA),Bridge 4 Resistance (ohms),Bridge 4 Excitation (uA),Signal 1 Vin (V),Signal 2 Vin (V),Digital Inputs (code),Drive 1 Iout (mA),Drive 1 Ipower (watts),Drive 2 Iout (mA),Drive 2 Ipower (watts),Pressure (),Map 20 (),Map 21 (),Map 22 (),Map 23 (),Map 24 (),Map 25 (),Map 26 (),Map 27 (),Map 28 (),Map 29 ()
,37300439.08,1.78658775,9.947,10000,2.99843742433504,,0.117193703244515,,,,,,,,,,125,1,0,-0.0161702560576589,0.000461819506010335,4373,0,1.7857269,1.7874486,9.947,9.947,,1.78075,,,,,,,,,,,,,,,,,,,,,,,1.78658775
,37300509.12,1.7990394,9.947,10000,2.99843742433504,,0.113496996144347,,,,,,,,,,125,1,0,-0.00859760911936425,0.000461732510003657,4373,0,1.7909966,1.8070822,9.947,9.947,,1.78395,,,,,,,,,,,,,,,,,,,,,,,1.7990394
,37302663.31,1.99174265,9999.192,,,0.00394196938319044,0.000109301602579164,,,,,,,,,5,125,0,21.3119996711612,0.249967693167972,5.7036656721409E-5,4373,0,1.9541748,2.0293105,9999.192,9999.192,0.249967693167972,1.95295,,,,,,,,,,,,,,,,,,,,,,,1.99174265
,37302718.80,2.1582111,9999.192,,,0.00394389146692662,3.02097101206442E-5,,,,,,,,,5,125,0,20.6400000723079,0.210566195725658,5.53894485726161E-5,4374,0,1.9729104,2.3435118,9999.192,9999.192,0.210566195725658,1.9666,,,,,,,,,,,,,,,,,,,,,,,2.1582111
,37303034.65,3.0298377,9999.192,,,0.00385099365750458,4.1064851008463E-5,,,,,,,,,5,125,0,6.75000047776848,0.210566195725658,5.631574383513E-5,4370,0,3.0101106,3.0495648,9999.192,9999.192,0.160287930684033,2.93745,,,,,,,,,,,,,,,,,,,,,,,3.0298377
,37303282.37,5.02612855,9999.192,,,0.00369328768768354,5.06832461885728E-5,,,,,,,,,5,125,0,6.98499970603734,0.210566195725658,5.60510633485849E-5,4370,0,5.0064688,5.0457883,9999.192,9999.192,0.125618825812654,5.02135,,,,,,,,,,,,,,,,,,,,,,,5.02612855
,37303525.29,7.05022,9999.192,,,0.00358700089039745,5.35415056123795E-5,,,,,,,,,5,125,0,6.67199974413961,0.210566195725658,5.61769205623046E-5,4370,0,7.0166659,7.0837741,9999.192,9999.192,0.154055169356897,7.04025,,,,,,,,,,,,,,,,,,,,,,,7.05022
,37303764.82,9.0312686,9999.192,,,0.00349819780973009,5.24720702751119E-5,,,,,,,,,5,125,0,6.71900021843612,0.210566195725658,5.53827062218812E-5,4370,0,9.0073757,9.0551615,9999.192,9999.192,0.12808760978811,9.0305,,,,,,,,,,,,,,,,,,,,,,,9.0312686
,37304007.40,11.03884175,9999.192,,,0.00346934154819834,5.18728062431255E-5,,,,,,,,,5,125,0,6.84400016907603,0.210566195725658,5.53944621154704E-5,4370,0,11.0094872,11.0681963,9999.192,9999.192,0.148666316493742,11.0465,,,,,,,,,,,,,,,,,,,,,,,11.03884175
,37304248.62,13.04472495,9999.192,,,0.00344737473659345,5.17724714789335E-5,,,,,,,,,5,125,0,6.95300053339452,0.210566195725658,5.5644447735029E-5,4370,0,13.0116606,13.0777893,9999.192,9999.192,0.150445500135864,13.0543,,,,,,,,,,,,,,,,,,,,,,,13.04472495
,37304490.14,15.04418705,9999.192,,,0.00346637313713485,5.2093453091086E-5,,,,,,,,,5,125,0,6.95400007534772,0.210566195725658,5.57609693861925E-5,4370,0,15.0129881,15.075386,9999.192,9999.192,0.150348532650621,15.06935,,,,,,,,,,,,,,,,,,,,,,,15.04418705
,37304731.06,17.04598235,9999.192,,,0.00348012995259748,5.00882818648844E-5,,,,,,,,,5,125,0,6.67199974413961,0.210566195725658,5.5442531550498E-5,4370,0,17.0167942,17.0751705,9999.192,9999.192,0.13729767994645,17.06745,,,,,,,,,,,,,,,,,,,,,,,17.04598235
,37304971.78,19.04172135,9999.192,,,0.00347060182371041,4.94180614380264E-5,,,,,,,,,5,125,0,7.03100000973791,0.210566195725658,5.55585586367622E-5,4370,0,19.0115433,19.0718994,9999.192,9999.192,0.158665946466032,19.06765,,,,,,,,,,,,,,,,,,,,,,,19.04172135
,37305211.57,21.03333475,9999.192,,,0.00342159661609468,4.90408348443653E-5,,,,,,,,,5,125,0,7.11000028531998,0.210566195725658,5.53741693690777E-5,4370,0,21.0047989,21.0618706,9999.192,9999.192,0.161494780725592,21.0654,,,,,,,,,,,,,,,,,,,,,,,21.03333475
,37305452.10,23.03974915,9999.192,,,0.0033973102677714,4.88885546402653E-5,,,,,,,,,5,125,0,6.95299990475178,0.210566195725658,5.51944071384684E-5,4370,0,23.009882,23.0696163,9999.192,9999.192,0.151367073576862,23.07695,,,,,,,,,,,,,,,,,,,,,,,23.03974915
,37305693.94,25.0431442,9999.192,,,0.00336400286380356,4.9962691371688E-5,,,,,,,,,5,125,0,6.96899949107319,0.210566195725658,5.51528650698834E-5,4370,0,25.0107765,25.0755119,9999.192,9999.192,0.151695076439531,25.08765,,,,,,,,,,,,,,,,,,,,,,,25.0431442
,37305935.50,27.05048275,9999.192,,,0.00330802852031736,5.14532334227409E-5,,,,,,,,,5,125,0,6.67200037278235,0.210566195725658,5.5063397482214E-5,4370,0,27.019249,27.0817165,9999.192,9999.192,0.167204532155704,27.1114,,,,,,,,,,,,,,,,,,,,,,,27.05048275
,37306174.25,29.0431976,9999.192,,,0.00328125014103359,5.08309374504213E-5,,,,,,,,,5,125,0,6.93799986038357,0.210566195725658,5.47096965671439E-5,4370,0,29.0097694,29.0766258,9999.192,9999.192,0.144593340021766,29.0933,,,,,,,,,,,,,,,,,,,,,,,29.0431976
,37306415.98,31.0436888,9999.192,,,0.00325226751664441,5.20119106938369E-5,,,,,,,,,5,125,0,6.95299990475178,0.210566195725658,5.47705442053094E-5,4370,0,31.0090714,31.0783062,9999.192,9999.192,0.166098283759839,31.1066,,,,,,,,,,,,,,,,,,,,,,,31.0436888
,37306655.44,33.0352497,9999.192,,,0.00320553929734909,5.16270688998631E-5,,,,,,,,,5,125,0,6.96899949107319,0.210566195725658,5.47811669878051E-5,4370,0,33.0045471,33.0659523,9999.192,9999.192,0.166222622965104,33.08715,,,,,,,,,,,,,,,,,,,,,,,33.0352497
,37306895.53,35.0431328,9999.192,,,0.00316292149856556,5.2930122308856E-5,,,,,,,,,5,125,0,7.28099991101772,0.210566195725658,5.41077546231043E-5,4370,0,35.0151482,35.0711174,9999.192,9999.192,0.145762802692137,35.09015,,,,,,,,,,,,,,,,,,,,,,,35.0431328
,37307132.78,37.03554535,9999.192,,,0.00313559507159183,5.20289154146418E-5,,,,,,,,,5,125,0,6.73399963416159,0.210566195725658,5.39375448775963E-5,4370,0,37.0073357,37.063755,9999.192,9999.192,0.156898199732281,37.07975,,,,,,,,,,,,,,,,,,,,,,,37.03554535
,37307377.18,39.07223705,9999.192,,,0.00312755067412485,5.20293159603304E-5,,,,,,,,,5,125,0,6.82800058275461,0.210566195725658,5.3854738997117E-5,4370,0,39.0222893,39.1221848,9999.192,9999.192,0.14742748000117,39.21645,,,,,,,,,,,,,,,,,,,,,,,39.07223705
,37307626.15,41.0909462,9999.192,,,0.00307444725723729,5.22353943369975E-5,,,,,,,,,5,125,0,6.95300053339452,0.210566195725658,5.35560826630052E-5,4370,0,41.0232086,41.1586838,9999.192,9999.192,0.156632508644234,41.3466,,,,,,,,,,,,,,,,,,,,,,,41.0909462
,37307853.98,43.04248045,9999.192,,,0.00304592677125826,5.18816186866663E-5,,,,,,,,,5,125,0,7.14100054465234,0.210566195725658,5.34278072108094E-5,4370,0,43.0158653,43.0690956,9999.192,9999.192,0.145889903229218,43.1077,,,,,,,,,,,,,,,,,,,,,,,43.04248045
,37308105.84,45.0683079,9999.192,,,0.00302323688309745,5.21896603053732E-5,,,,,,,,,5,125,0,6.82799995411187,0.210566195725658,5.31775920118612E-5,4370,0,45.0076714,45.1289444,9999.192,9999.192,0.145677624480248,45.36055,,,,,,,,,,,,,,,,,,,,,,,45.0683079
,37308339.38,47.0672474,9999.192,,,0.0029754036913216,5.06848023554828E-5,,,,,,,,,5,125,0,6.96900011971593,0.210566195725658,5.27574016470767E-5,4370,0,47.0239525,47.1105423,9999.192,9999.192,0.13812332667864,47.24825,,,,,,,,,,,,,,,,,,,,,,,47.0672474
,37308578.43,49.0131893,9999.192,,,0.00295985440419992,5.14584742630174E-5,,,,,,,,,5,125,0,6.93800048902631,0.210566195725658,5.28331621343289E-5,4370,0,49.0009079,49.0254707,9999.192,9999.192,0.138312152330117,49.0017,,,,,,,,,,,,,,,,,,,,,,,49.0131893
,37309203.98,55.03120425,9999.192,,,0.00286043036908313,4.97522067432187E-5,,,,,,,,,5,125,0,7.06300043966621,0.210566195725658,5.22192068400378E-5,4370,0,55.0223122,55.0400963,9999.192,9999.192,0.147686794618024,55.00995,,,,,,,,,,,,,,,,,,,,,,,55.03120425
,37309528.60,65.1877403,9999.192,,,0.00272613834644002,4.77327798175428E-5,,,,,,,,,5,125,0,6.95299990475178,0.210566195725658,5.12511033296253E-5,4374,0,65.0671234,65.3083572,9999.192,9999.192,0.147872932033084,66.805,,,,,,,,,,,,,,,,,,,,,,,65.1877403
,37309827.63,75.1540909,9999.192,,,0.0025989987371352,4.74976440636044E-5,,,,,,,,,5,125,0,6.60900031216443,0.210566195725658,5.10694796768119E-5,4374,0,75.0423584,75.2658234,9999.192,9999.192,0.160866357762811,76.80275,,,,,,,,,,,,,,,,,,,,,,,75.1540909
,37310131.58,85.140007,9999.192,,,0.00248376112166833,4.81062989102227E-5,,,,,,,,,5,125,0,7.26599986664951,0.210566195725658,5.03864517491453E-5,4374,0,85.0331421,85.2468719,9999.192,9999.192,0.161418059165415,87.14295,,,,,,,,,,,,,,,,,,,,,,,85.140007
,37310434.53,95.15465545,9999.192,,,0.00238454131782179,4.90507462005255E-5,,,,,,,,,5,125,0,7.17199954669923,0.210566195725658,4.97253370764026E-5,4374,0,95.0427933,95.2665176,9999.192,9999.192,0.158326393206992,97.6947,,,,,,,,,,,,,,,,,,,,,,,95.15465545
,37310744.86,105.14829635,9999.192,,,0.00227952147832828,4.93702951700086E-5,,,,,,,,,5,125,0,6.74999984912574,0.210566195725658,4.91642591377139E-5,4374,0,105.0503082,105.2462845,9999.192,9999.192,0.147916968729182,108.4497,,,,,,,,,,,,,,,,,,,,,,,105.14829635
,37311042.44,115.09480285,9999.192,,,0.00217856196458979,5.18498827723762E-5,,,,,,,,,5,125,0,6.53099957853556,0.210566195725658,4.88293363187813E-5,4374,0,115.0283966,115.1612091,9999.192,9999.192,0.138145631522369,116.98935,,,,,,,,,,,,,,,,,,,,,,,115.09480285
,37311348.22,125.2608299,9999.192,,,0.00208189174880883,5.39822268662842E-5,,,,,,,,,5,125,0,6.54700042214245,0.210566195725658,4.87260653714078E-5,4374,0,125.0899353,125.4317245,9999.192,9999.192,0.134162730432923,130.9066,,,,,,,,,,,,,,,,,,,,,,,125.2608299
,37311644.11,135.20269775,9999.192,,,0.00202058972219461,5.40815322269644E-5,,,,,,,,,5,125,0,6.76600006408989,0.210566195725658,4.82236089003294E-5,4374,0,135.0618591,135.3435364,9999.192,9999.192,0.150145524081662,138.64645,,,,,,,,,,,,,,,,,,,,,,,135.20269775
,37311945.12,145.16255185,9999.192,,,0.00193467452530345,5.67697664395501E-5,,,,,,,,,5,125,0,6.56200046651065,0.210566195725658,4.8007997626948E-5,4374,0,145.031723,145.2933807,9999.192,9999.192,0.144756316038892,148.9587,,,,,,,,,,,,,,,,,,,,,,,145.16255185
,37312254.87,155.2808838,9999.192,,,0.00186425629847683,5.59733571270934E-5,,,,,,,,,5,125,0,6.96799994911998,0.210566195725658,4.7585092166629E-5,4374,0,155.1169586,155.444809,9999.192,9999.192,0.147009470892006,161.3534,,,,,,,,,,,,,,,,,,,,,,,155.2808838
,37312566.24,165.15281675,9999.192,,,0.00181189937439027,5.64092453081675E-5,,,,,,,,,5,125,0,6.82799995411187,0.210566195725658,4.75841218102029E-5,4374,0,165.0537262,165.2519073,9999.192,9999.192,0.147163485944961,173.43165,,,,,,,,,,,,,,,,,,,,,,,165.15281675
,37312857.45,175.28142545,9999.192,,,0.00174518387483981,6.02945908688306E-5,,,,,,,,,5,125,0,6.90600005909801,0.210566195725658,4.70838572971149E-5,4374,0,175.1081085,175.4547424,9999.192,9999.192,0.124223973304884,181.7386,,,,,,,,,,,,,,,,,,,,,,,175.28142545
,37313150.87,185.1467819,9999.192,,,0.00168781985669134,6.0103325482007E-5,,,,,,,,,5,125,0,6.81199973914772,0.210566195725658,4.71432668009773E-5,4374,0,185.0432434,185.2503204,9999.192,9999.192,0.14230478197587,188.0791,,,,,,,,,,,,,,,,,,,,,,,185.1467819
,37313461.39,195.0797348,9999.192,,,0.00163668449367724,5.87954938117909E-5,,,,,,,,,5,125,0,6.81299990974367,0.210566195725658,4.7801310724767E-5,4374,0,195.0319214,195.1275482,9999.192,9999.192,0.144296535260857,197.9803,,,,,,,,,,,,,,,,,,,,,,,195.0797348
,37313777.16,205.09849545,9999.192,,,0.00158541149698584,6.27465185957171E-5,,,,,,,,,5,125,0,7.15599996037781,0.210566195725658,4.70311324290683E-5,4374,0,205.0367889,205.160202,9999.192,9999.192,0.135165193217232,213.684,,,,,,,,,,,,,,,,,,,,,,,205.09849545
,37314079.32,215.0993042,9999.192,,,0.0015444810969472,6.51867013963972E-5,,,,,,,,,5,125,0,7.0159999653697,0.210566195725658,4.70832370931683E-5,4374,0,215.0489807,215.1496277,9999.192,9999.192,0.129921627585972,223.7293,,,,,,,,,,,,,,,,,,,,,,,215.0993042
,37314365.06,225.08999635,9999.192,,,0.00148137230171845,6.51708508464167E-5,,,,,,,,,5,125,0,6.96900011971593,0.210566195725658,4.72553359976794E-5,4374,0,225.0284729,225.1515198,9999.192,9999.192,0.117118671751374,227.50805,,,,,,,,,,,,,,,,,,,,,,,225.08999635
,37314665.76,235.20077515,9999.192,,,0.00144435666807134,6.85791700638877E-5,,,,,,,,,5,125,0,7.03200018033385,0.210566195725658,4.61403163645604E-5,4374,0,235.0779419,235.3236084,9999.192,9999.192,0.112814817815939,238.87225,,,,,,,,,,,,,,,,,,,,,,,235.20077515
,37314977.06,245.237854,9999.192,,,0.00140804827208366,7.21218048733698E-5,,,,,,,,,5,125,0,6.82799995411187,0.210566195725658,4.51936148574846E-5,4374,0,245.0760956,245.3996124,9999.192,9999.192,0.116220105809813,252.64735,,,,,,,,,,,,,,,,,,,,,,,245.237854
,37315297.22,255.2644043,9999.192,,,0.00134185193618042,7.06097772193492E-5,,,,,,,,,5,125,0,6.82799995411187,0.210566195725658,4.53106415325674E-5,4374,0,255.0962982,255.4325104,9999.192,9999.192,0.123678844243272,270.3803,,,,,,,,,,,,,,,,,,,,,,,255.2644043
,37315587.39,265.0939026,9999.192,,,0.00129828750882568,7.16980914908806E-5,,,,,,,,,5,125,0,7.09400007035583,0.210566195725658,4.59088398133981E-5,4374,0,265.0231018,265.1647034,9999.192,9999.192,0.11753570278425,273.23085,,,,,,,,,,,,,,,,,,,,,,,265.0939026
,37315881.82,275.2008972,9999.192,,,0.00129768530920281,8.04984290608925E-5,,,,,,,,,5,125,0,7.0159999653697,0.210566195725658,4.48904964970417E-5,4374,0,275.059082,275.3427124,9999.192,9999.192,0.0977069996610906,280.8359,,,,,,,,,,,,,,,,,,,,,,,275.2008972
,37316203.34,285.20155335,9999.192,,,0.00127004737771161,8.72329505391383E-5,,,,,,,,,5,125,0,6.7810001084581,0.210566195725658,4.47467511100529E-5,4374,0,285.0462036,285.3569031,9999.192,9999.192,0.0869549624405562,299.54155,,,,,,,,,,,,,,,,,,,,,,,285.20155335
,37316497.20,295.1161804,9999.192,,,0.00124001762006781,9.24627958914167E-5,,,,,,,,,5,125,0,6.81299990974367,0.210566195725658,4.51422032932517E-5,4374,0,295.019104,295.2132568,9999.192,9999.192,0.0727634386604659,305.57715,,,,,,,,,,,,,,,,,,,,,,,295.1161804
,37316899.32,299.76348875,9999.192,,,0.00123944712270919,9.94837629541239E-5,,,,,,,,,5,125,0,7.23400006536394,0.210566195725658,4.45535008736766E-5,4370,0,299.7616577,299.7653198,9999.192,9999.192,0.0615191978235189,300.26505,,,,,,,,,,,,,,,,,,,,,,,299.76348875
,37317377.88,289.72361755,9999.192,,,0.00125581888684597,9.71880905794974E-5,,,,,,,,,5,125,0,7.01499979477376,0.210566195725658,5.2368792610227E-5,4374,0,289.5315857,289.9156494,9999.192,9999.192,0.0790170656925467,271.58305,,,,,,,,,,,,,,,,,,,,,,,289.72361755
,37317732.78,279.5782623,9999.192,,,0.00127956353626466,8.96959025461284E-5,,,,,,,,,5,125,0,7.18700021971017,0.210566195725658,5.20649352481113E-5,4374,0,279.3280334,279.8284912,9999.192,9999.192,0.0987922211961146,266.5958,,,,,,,,,,,,,,,,,,,,,,,279.5782623
,37318074.16,269.6442566,9999.192,,,0.00130603343842363,8.51319670501608E-5,,,,,,,,,5,125,0,7.00000037904829,0.210566195725658,5.01808615525154E-5,4374,0,269.4155884,269.8729248,9999.192,9999.192,0.116772056594562,263.21535,,,,,,,,,,,,,,,,,,,,,,,269.6442566
,37318425.72,259.8253479,9999.192,,,0.00135121726857111,7.86223325946333E-5,,,,,,,,,5,125,0,6.92200027406216,0.210566195725658,4.81296833374818E-5,4374,0,259.7086487,259.9420471,9999.192,9999.192,0.124750908396245,262.0105,,,,,,,,,,,,,,,,,,,,,,,259.8253479
,37318961.18,249.69506835,9999.192,,,0.00137413290215138,7.57058646080475E-5,,,,,,,,,5,125,0,7.375000230968,0.210566195725658,5.1959213047766E-5,4374,0,249.4636688,249.9264679,9999.192,9999.192,0.139350891281594,232.48965,,,,,,,,,,,,,,,,,,,,,,,249.69506835
,37319280.38,239.69589995,9999.192,,,0.00141649423922768,7.35809061953409E-5,,,,,,,,,5,125,0,7.06300043966621,0.210566195725658,5.11952626336816E-5,4374,0,239.4874115,239.9043884,9999.192,9999.192,0.15133699884894,233.6373,,,,,,,,,,,,,,,,,,,,,,,239.69589995
,37319605.10,229.8857651,9999.192,,,0.00147037265789847,6.80912687937366E-5,,,,,,,,,5,125,0,6.28100030589849,0.210566195725658,4.84706155626526E-5,4374,0,229.805481,229.9660492,9999.192,9999.192,0.160765635457948,232.73005,,,,,,,,,,,,,,,,,,,,,,,229.8857651
,37320083.05,219.7052536,9999.192,,,0.00151175884429391,6.55640734789261E-5,,,,,,,,,5,125,0,7.21900002099574,0.210566195725658,5.21730914398538E-5,4374,0,219.4926758,219.9178314,9999.192,9999.192,0.166095992512626,207.4449,,,,,,,,,,,,,,,,,,,,,,,219.7052536
,37320393.28,209.76006315,9999.192,,,0.00155804395740729,6.31125348703945E-5,,,,,,,,,5,125,0,6.81199973914772,0.210566195725658,5.02001985617662E-5,4374,0,209.6143188,209.9058075,9999.192,9999.192,0.170454634062424,209.0622,,,,,,,,,,,,,,,,,,,,,,,209.76006315
,37320864.35,199.63884735,9999.192,,,0.00159089488578018,6.01387063187672E-5,,,,,,,,,5,125,0,7.07800048403442,0.210566195725658,5.24452721425598E-5,4374,0,199.3872528,199.8904419,9999.192,9999.192,0.171551089513194,185.58865,,,,,,,,,,,,,,,,,,,,,,,199.63884735
,37321181.18,189.8218155,9999.192,,,0.00165087066589848,5.9050217886884E-5,,,,,,,,,5,125,0,6.71800004784018,0.210566195725658,5.00941645900861E-5,4374,0,189.69487,189.948761,9999.192,9999.192,0.173789738856878,191.42885,,,,,,,,,,,,,,,,,,,,,,,189.8218155
,37321615.77,179.63884735,9999.192,,,0.00171850113208036,5.75592625268929E-5,,,,,,,,,5,125,0,6.56200046651065,0.210566195725658,5.32884060617082E-5,4374,0,179.3685608,179.9091339,9999.192,9999.192,0.168599957814042,171.15695,,,,,,,,,,,,,,,,,,,,,,,179.63884735
,37322079.81,169.75200655,9999.192,,,0.00177800450757374,5.6714221035457E-5,,,,,,,,,5,125,0,6.85900021344423,0.210566195725658,5.2807685899275E-5,4374,0,169.5405884,169.9634247,9999.192,9999.192,0.166170428077696,159.5297,,,,,,,,,,,,,,,,,,,,,,,169.75200655
,37322375.74,159.7559662,9999.192,,,0.0018315662235787,5.59097455559682E-5,,,,,,,,,5,125,0,6.46900031715631,0.210566195725658,5.30434828038721E-5,4374,0,159.5975189,159.9144135,9999.192,9999.192,0.170670267961695,159.064,,,,,,,,,,,,,,,,,,,,,,,159.7559662
,37322811.89,149.66426085,9999.192,,,0.00189629462526534,5.44864672785137E-5,,,,,,,,,5,125,0,7.04699959605932,0.210566195725658,5.56386942836264E-5,4374,0,149.4181366,149.9103851,9999.192,9999.192,0.168377693211745,140.3181,,,,,,,,,,,,,,,,,,,,,,,149.66426085
,37323226.80,139.6656723,9999.192,,,0.0019827709264115,5.5818184621806E-5,,,,,,,,,5,125,0,6.87499979976565,0.210566195725658,5.60804490896111E-5,4374,0,139.4573364,139.8740082,9999.192,9999.192,0.159446749927709,130.9004,,,,,,,,,,,,,,,,,,,,,,,139.6656723
,37323619.07,129.6533127,9999.192,,,0.00204027487191082,5.24866138616172E-5,,,,,,,,,5,125,0,7.07799985539168,0.210566195725658,5.649740370009E-5,4374,0,129.4312744,129.875351,9999.192,9999.192,0.160641941220028,122.05105,,,,,,,,,,,,,,,,,,,,,,,129.6533127
,37323994.00,119.5762558,9999.192,,,0.00212826859398795,5.37314787741607E-5,,,,,,,,,5,125,0,6.90600005909801,0.210566195725658,5.6678474614034E-5,4374,0,119.3355484,119.8169632,9999.192,9999.192,0.156794243533889,112.45735,,,,,,,,,,,,,,,,,,,,,,,119.5762558
,37324329.85,109.7278366,9999.192,,,0.00222524948256053,5.58225211827663E-5,,,,,,,,,5,125,0,7.00000037904829,0.210566195725658,5.75652452206433E-5,4374,0,109.5437927,109.9118805,9999.192,9999.192,0.151749982628455,106.82395,,,,,,,,,,,,,,,,,,,,,,,109.7278366
,37324695.82,99.8660202,9999.192,,,0.00231936395827155,5.43759002350747E-5,,,,,,,,,5,125,0,6.95299990475178,0.210566195725658,5.62650763382191E-5,4374,0,99.7718582,99.9601822,9999.192,9999.192,0.148712767791894,97.2178,,,,,,,,,,,,,,,,,,,,,,,99.8660202
,37325011.23,89.6325264,9999.192,,,0.00239363803408339,5.46540590819757E-5,,,,,,,,,5,125,0,6.68699978850782,0.210566195725658,5.83192451037972E-5,4374,0,89.4426498,89.822403,9999.192,9999.192,0.144959166820824,85.86355,,,,,,,,,,,,,,,,,,,,,,,89.6325264
,37325323.33,79.84098055,9999.192,,,0.00253382469336278,5.77105900202996E-5,,,,,,,,,5,125,0,7.14100054465234,0.210566195725658,5.59754476313239E-5,4374,0,79.7491074,79.9328537,9999.192,9999.192,0.137930798868416,77.8817,,,,,,,,,,,,,,,,,,,,,,,79.84098055
,37325627.46,69.86782835,9999.192,,,0.00266776637788317,5.95749087116951E-5,,,,,,,,,5,125,0,6.48399973288178,0.210566195725658,5.64784467475626E-5,4374,0,69.8037033,69.9319534,9999.192,9999.192,0.131765265175401,68.5755,,,,,,,,,,,,,,,,,,,,,,,69.86782835
,37325927.74,59.89292525,9999.192,,,0.00280090644430903,6.15266036281524E-5,,,,,,,,,5,125,0,6.68799995910376,0.210566195725658,5.74224244767107E-5,4370,0,59.8167114,59.9691391,9999.192,9999.192,0.129046971460873,58.79855,,,,,,,,,,,,,,,,,,,,,,,59.89292525
,37326871.17,50.0686302,9999.192,,,0.00293039214869596,6.47441595345823E-5,,,,,,,,,5,125,0,6.59400026779622,0.210566195725658,5.44180187024747E-5,4370,0,50.060318,50.0769424,9999.192,9999.192,0.124704781554429,49.91505,,,,,,,,,,,,,,,,,,,,,,,50.0686302
,37327119.76,47.9386158,9999.192,,,0.00296500841688372,6.41037861519676E-5,,,,,,,,,5,125,0,6.62499989848584,0.210566195725658,5.56402548068588E-5,4370,0,47.9122925,47.9649391,9999.192,9999.192,0.125336995749537,47.6086,,,,,,,,,,,,,,,,,,,,,,,47.9386158
,37327353.11,45.9738045,9999.192,,,0.00299361122176246,6.75480725726826E-5,,,,,,,,,5,125,0,6.93799986038357,0.210566195725658,5.61994846249942E-5,4370,0,45.9650307,45.9825783,9999.192,9999.192,0.119057087204108,45.8092,,,,,,,,,,,,,,,,,,,,,,,45.9738045
,37327608.00,43.92193985,9999.192,,,0.00302377894543566,6.64049068280087E-5,,,,,,,,,5,125,0,6.90600005909801,0.210566195725658,5.6075472423285E-5,4370,0,43.8808212,43.9630585,9999.192,9999.192,0.115677121878566,43.5525,,,,,,,,,,,,,,,,,,,,,,,43.92193985
,37327836.78,41.94804765,9999.192,,,0.00307444999723081,6.71010878525334E-5,,,,,,,,,5,125,0,6.85900021344423,0.210566195725658,5.64461501833113E-5,4370,0,41.9208069,41.9752884,9999.192,9999.192,0.117301243890954,41.6922,,,,,,,,,,,,,,,,,,,,,,,41.94804765
,37328085.77,39.93605995,9999.192,,,0.00309751979349642,6.83902202333918E-5,,,,,,,,,5,125,0,6.79699969477951,0.210566195725658,5.67218138049432E-5,4370,0,39.8989296,39.9731903,9999.192,9999.192,0.113744826826087,39.6176,,,,,,,,,,,,,,,,,,,,,,,39.93605995
,37328310.95,37.9516106,9999.192,,,0.00310630812560637,6.97567485310611E-5,,,,,,,,,5,125,0,6.98400016408414,0.210566195725658,5.70237545732759E-5,4370,0,37.9371262,37.966095,9999.192,9999.192,0.114215224321975,37.78795,,,,,,,,,,,,,,,,,,,,,,,37.9516106
,37328555.74,35.933424,9999.192,,,0.00315597733232407,6.89946860479643E-5,,,,,,,,,5,125,0,7.36000018659979,0.210566195725658,5.69297278393136E-5,4370,0,35.8895073,35.9773407,9999.192,9999.192,0.112213364457918,35.70425,,,,,,,,,,,,,,,,,,,,,,,35.933424
,37328796.58,33.935297,9999.192,,,0.00320548886254021,6.92385397263072E-5,,,,,,,,,5,125,0,6.60999985411763,0.210566195725658,5.71722526146247E-5,4370,0,33.8942413,33.9763527,9999.192,9999.192,0.112333997684083,33.69295,,,,,,,,,,,,,,,,,,,,,,,33.935297
,37329034.25,31.9343405,9999.192,,,0.00322952610774787,6.79955482910762E-5,,,,,,,,,5,125,0,6.34299956727773,0.210566195725658,5.74096761340484E-5,4370,0,31.8937912,31.9748898,9999.192,9999.192,0.10806041757257,31.74525,,,,,,,,,,,,,,,,,,,,,,,31.9343405
,37329269.83,29.9821377,9999.192,,,0.00327430373788497,7.03112404757879E-5,,,,,,,,,5,125,0,6.81299990974367,0.210566195725658,5.74788493375993E-5,4370,0,29.9748955,29.9893799,9999.192,9999.192,0.110712311110589,29.8793,,,,,,,,,,,,,,,,,,,,,,,29.9821377
,37329514.37,27.9435234,9999.192,,,0.00330921721814347,7.05123063996376E-5,,,,,,,,,5,125,0,7.18800039030611,0.210566195725658,5.76841415362965E-5,4370,0,27.910429,27.9766178,9999.192,9999.192,0.111568386233571,27.79855,,,,,,,,,,,,,,,,,,,,,,,27.9435234
,37329751.87,25.97437385,9999.192,,,0.00333605377213073,7.04134126080446E-5,,,,,,,,,5,125,0,7.09299989975989,0.210566195725658,5.77387813273928E-5,4370,0,25.960907,25.9878407,9999.192,9999.192,0.112654600197091,25.86035,,,,,,,,,,,,,,,,,,,,,,,25.97437385
,37329990.81,23.97599315,9999.192,,,0.00337466154529098,6.89738564117637E-5,,,,,,,,,5,125,0,6.7810001084581,0.210566195725658,5.78051841286552E-5,4370,0,23.9647045,23.9872818,9999.192,9999.192,0.112817498135016,23.88415,,,,,,,,,,,,,,,,,,,,,,,23.97599315
,37330230.57,21.98180675,9999.192,,,0.00340627796880057,6.83276776327802E-5,,,,,,,,,5,125,0,7.00000037904829,0.210566195725658,5.80527163985117E-5,4370,0,21.9714069,21.9922066,9999.192,9999.192,0.114486979889891,21.8993,,,,,,,,,,,,,,,,,,,,,,,21.98180675
,37330470.93,19.9846096,9999.192,,,0.00343742817640523,6.66732022872009E-5,,,,,,,,,5,125,0,6.5310002071783,0.210566195725658,5.79235301281662E-5,4370,0,19.9772987,19.9919205,9999.192,9999.192,0.11892607612862,19.90425,,,,,,,,,,,,,,,,,,,,,,,19.9846096
,37330713.38,17.9615297,9999.192,,,0.00344313095452414,6.7619012634324E-5,,,,,,,,,5,125,0,6.93799986038357,0.210566195725658,5.80213582691536E-5,4370,0,17.9457855,17.9772739,9999.192,9999.192,0.118077096920802,17.86475,,,,,,,,,,,,,,,,,,,,,,,17.9615297
,37330949.82,15.97940305,9999.192,,,0.00345794502295895,6.72506582329651E-5,,,,,,,,,5,125,0,6.93799986038357,0.210566195725658,5.78647556962954E-5,4370,0,15.9661341,15.992672,9999.192,9999.192,0.11862107911068,15.9018,,,,,,,,,,,,,,,,,,,,,,,15.97940305
,37331190.63,13.98180675,9999.192,,,0.00343229296475988,6.63063129340359E-5,,,,,,,,,5,125,0,6.74999984912574,0.210566195725658,5.75464821654466E-5,4370,0,13.9715233,13.9920902,9999.192,9999.192,0.118065330739952,13.90425,,,,,,,,,,,,,,,,,,,,,,,13.98180675
,37331432.99,11.9780531,9999.192,,,0.00343717294792034,6.76461316260935E-5,,,,,,,,,5,125,0,7.20299980603159,0.210566195725658,5.76114853417633E-5,4370,0,11.9656429,11.9904633,9999.192,9999.192,0.117395868766853,11.91725,,,,,,,,,,,,,,,,,,,,,,,11.9780531
,37331706.75,9.9928956,9999.192,,,0.00346431398589238,6.66968434343935E-5,,,,,,,,,5,125,0,6.84399954043329,0.210566195725658,5.76590275584844E-5,4370,0,9.9923229,9.9934683,9999.192,9999.192,0.115768560729439,9.9353,,,,,,,,,,,,,,,,,,,,,,,9.9928956
,37331980.70,7.96585465,9999.192,,,0.0035183691351905,6.65910165087189E-5,,,,,,,,,5,125,0,6.99999975040555,0.210566195725658,5.77803898717141E-5,4370,0,7.9455061,7.9862032,9999.192,9999.192,0.114884434111935,7.95845,,,,,,,,,,,,,,,,,,,,,,,7.96585465
,37332270.68,5.96892575,9999.192,,,0.00361483430293125,6.66861919342823E-5,,,,,,,,,5,125,0,6.67200037278235,0.210566195725658,5.83064661098308E-5,4370,0,5.9596663,5.9781852,9999.192,9999.192,0.105862458689974,5.9498,,,,,,,,,,,,,,,,,,,,,,,5.96892575
,37332562.76,3.9361216,9999.192,,,0.00373560372806918,6.5349930533413E-5,,,,,,,,,5,125,0,6.64100011344999,0.210566195725658,5.87682306947832E-5,4370,0,3.8875575,3.9846857,9999.192,9999.192,0.112449321341307,3.9219,,,,,,,,,,,,,,,,,,,,,,,3.9361216
,37332846.17,2.00560265,9999.192,,,0.00391796582186789,4.74073106995197E-5,,,,,,,,,5,125,0,6.98400016408414,0.210566195725658,5.89789723754484E-5,4370,0,1.9975749,2.0136304,9999.192,9999.192,0.147368787621325,2.0038,,,,,,,,,,,,,,,,,,,,,,,2.00560265
,37341835.77,1.8158752,9.937,1000,10.0020797337467,,0.111129361947592,,,,,,,,,,125,1,0,-0.0113387915131988,0.000199216572412326,4374,0,1.7964519,1.8352985,9.937,9.937,,1.7883,,,,,,,,,,,,,,,,,,,,,,,1.8158752
,37341905.73,1.80853515,9.937,1000,10.0020797337467,,0.115055154328386,,,,,,,,,,125,1,0,-0.0187295144789101,0.00019926261337586,4374,0,1.7984347,1.8186356,9.937,9.937,,1.78775,,,,,,,,,,,,,,,,,,,,,,,1.80853515
,37342130.87,2.4173056125,9.937,100,5.00030447240857,,5.75734843869008E-8,2.09709742540225E-6,7.59406839612043E-8,2.09847196767296E-6,2.07390473453966,1.51674160271546E-8,-7.47490553917706E-12,1.51674178690705E-8,-0.0282368799150845,800,25,5,13.4965986394558,-0.0187295144789101,8.90565004041833E-5,4370,0,2.3568604,2.5180821,9.937,9.937,,2.3837125,,,,,,,,,,,,,,,,,,,,,,,2.4173056125
,37342249.66,3.3937876625,9.937,100,5.00030447240857,,4.23006683836712E-8,2.16358346721531E-6,-3.59996972416682E-8,2.16388294457185E-6,-0.953252060553666,1.51681794502077E-8,-8.54321987057495E-12,1.51681818561194E-8,-0.0322708728415364,800,25,5,13.4965986394558,-0.0187295144789101,8.85120392423892E-5,4370,0,3.3248105,3.4559565,9.937,9.937,,3.3351125,,,,,,,,,,,,,,,,,,,,,,,3.3937876625
,37342375.84,4.395218475,9.937,100,5.00030447240857,,5.31871264427262E-8,1.98373443992718E-6,3.55971918358765E-8,1.98405380174526E-6,1.02803577834024,1.51642581966637E-8,-7.49414022023828E-12,1.51642600484567E-8,-0.0283154352276256,800,25,5,13.4965986394558,-0.0187295144789101,8.89620628929341E-5,4370,0,4.3247766,4.4605045,9.937,9.937,,4.407175,,,,,,,,,,,,,,,,,,,,,,,4.395218475
,37342497.17,5.391698,9.937,100,5.00030447240857,,4.1318145311649E-8,2.09343966506799E-6,7.36275740029592E-8,2.09473402868563E-6,2.0142979023374,1.51645682495084E-8,-7.84072106903709E-12,1.51645702765E-8,-0.0296243307538475,800,25,5,13.4965986394558,-0.0187295144789101,8.89007106322245E-5,4370,0,5.3208084,5.464241,9.937,9.937,,5.409525,,,,,,,,,,,,,,,,,,,,,,,5.391698
,37342615.68,6.3755026,9.937,100,5.00030447240857,,6.22257696469062E-8,2.03413556258866E-6,-9.81687221441453E-8,2.03650302847683E-6,-2.7629883070432,1.51637662047029E-8,-7.8997711148408E-12,1.51637682624496E-8,-0.0298490161970335,800,25,5,13.4965986394558,-0.0187295144789101,8.89479293878491E-5,4370,0,6.3117156,6.4371557,9.937,9.937,,6.3833375,,,,,,,,,,,,,,,,,,,,,,,6.3755026
,37342735.93,7.372459825,9.937,100,5.00030447240857,,4.78802711413975E-8,2.09384420807961E-6,1.870316020422E-7,2.10218086469052E-6,5.10437033624171,1.5163646346654E-8,-8.33323998946114E-12,1.51636486364358E-8,-0.0314871121420879,800,25,5,13.4965986394558,-0.0187295144789101,8.85181423468577E-5,4370,0,7.3070903,7.4472451,9.937,9.937,,7.370275,,,,,,,,,,,,,,,,,,,,,,,7.372459825
,37342855.84,8.3797819625,9.937,100,5.00030447240857,,7.16871220318082E-8,1.91372722253555E-6,1.34834391757557E-7,1.91847131734469E-6,4.03019621575127,1.51646051222037E-8,-6.51817367881528E-12,1.51646065230508E-8,-0.0246273355567155,800,25,5,13.4965986394558,-0.0187295144789101,8.88396795875396E-5,4370,0,8.320219,8.4553337,9.937,9.937,,8.38115,,,,,,,,,,,,,,,,,,,,,,,8.3797819625
,37342977.49,9.3758497,9.937,100,5.00030447240857,,1.03224878741162E-7,1.85949918605742E-6,1.06051784360793E-7,1.86252092710775E-6,3.26418230198364,1.51641388922481E-8,-8.18219798343823E-12,1.51641410997047E-8,-0.0309153964776101,800,25,5,13.4965986394558,-0.0187295144789101,8.9008960432534E-5,4370,0,9.3004417,9.4304943,9.937,9.937,,9.38275,,,,,,,,,,,,,,,,,,,,,,,9.3758497
,37343098.35,10.3747515875,9.937,100,5.00030447240857,,4.93996187262731E-8,2.01684554143234E-6,3.1378175272099E-8,2.01708961820711E-6,0.891338448528649,1.51636049177946E-8,-7.41924439389716E-12,1.51636067328374E-8,-0.0280336608167886,800,25,5,13.4965986394558,-0.0187295144789101,8.90317667702847E-5,4370,0,10.3063326,10.4452667,9.937,9.937,,10.3806125,,,,,,,,,,,,,,,,,,,,,,,10.3747515875
,37343218.47,11.3681873125,9.937,100,5.00030447240857,,4.41123473214934E-8,2.03242998535696E-6,6.07192134477998E-8,2.0333367818096E-6,1.71121279710522,1.51651023608157E-8,-7.7211006165285E-12,1.5165104326361E-8,-0.0291713454860201,800,25,5,13.4965986394558,-0.0187295144789101,8.89421474994053E-5,4370,0,11.3041229,11.4332886,9.937,9.937,,11.3803625,,,,,,,,,,,,,,,,,,,,,,,11.3681873125
,37343338.73,12.3639712375,9.937,100,5.00030447240857,,3.90837133750806E-8,1.98713600515092E-6,-6.52824864925804E-9,1.98714672860299E-6,-0.188230573343162,1.51648993923026E-8,-7.72895100765876E-12,1.51649013618732E-8,-0.02920139613218,800,25,5,13.4965986394558,-0.0187295144789101,8.92315631376215E-5,4370,0,12.2945108,12.4337835,9.937,9.937,,12.3872375,,,,,,,,,,,,,,,,,,,,,,,12.3639712375
,37343458.42,13.3631539125,9.937,100,5.00030447240857,,6.55068981677494E-8,2.06576296653763E-6,5.55742217445566E-8,2.06651037453018E-6,1.54102893940284,1.51647536267608E-8,-7.51621860439524E-12,1.51647554894201E-8,-0.0283979271450789,800,25,5,13.4965986394558,-0.0187295144789101,8.92556543394708E-5,4370,0,13.2928505,13.4371519,9.937,9.937,,13.3727,,,,,,,,,,,,,,,,,,,,,,,13.3631539125
,37343578.85,14.359383225,9.937,100,5.00030447240857,,5.45108925291336E-8,2.04972325077476E-6,-1.02657279988759E-8,2.04974895778434E-6,-0.286954821784377,1.51649460919076E-8,-7.69980990304147E-12,1.51649480466481E-8,-0.0290912061218478,800,25,5,13.4965986394558,-0.0187295144789101,8.91975142390079E-5,4370,0,14.2862282,14.4284286,9.937,9.937,,14.3831,,,,,,,,,,,,,,,,,,,,,,,14.359383225
,37343699.92,15.3623503375,9.937,100,5.00030447240857,,5.65947929494533E-8,2.06889776685247E-6,-7.18723312574916E-8,2.0701457923749E-6,-1.98962266001547,1.51633651258273E-8,-7.64391334185748E-12,1.51633670524909E-8,-0.0288830304302223,800,25,5,13.4965986394558,-0.0187295144789101,8.93221460565749E-5,4370,0,15.2896595,15.4345045,9.937,9.937,,15.39055,,,,,,,,,,,,,,,,,,,,,,,15.3623503375
,37343819.71,16.3602583125,9.937,100,5.00030777095281,,7.87429103998912E-8,2.28363335769473E-6,-1.00902092808415E-7,2.28586144477508E-6,-2.52996225531444,1.51654558383149E-8,-8.59477951125248E-12,1.51654582737916E-8,-0.0324714630650078,800,25,5,13.4965986394558,-0.0187295144789101,8.93279279450187E-5,4370,0,16.2899303,16.4312782,9.937,9.937,,16.38685,,,,,,,,,,,,,,,,,,,,,,,16.3602583125
,37343939.58,17.3566751375,9.937,100,5.00028658091165,,5.80739893311579E-8,2.19252092014812E-6,2.07516654254375E-8,2.19261912262597E-6,0.542274116564956,1.51674774200112E-8,-8.00228551886238E-12,1.51674795309941E-8,-0.0302289650052785,800,25,5,13.4965986394558,-0.0187295144789101,8.94875723092734E-5,4370,0,17.2852364,17.4280663,9.937,9.937,,17.3796125,,,,,,,,,,,,,,,,,,,,,,,17.3566751375
,37344058.12,18.3382971375,9.937,100,5.00022732751541,,5.35243686262658E-8,2.00875883514673E-6,-3.43524914537213E-8,2.00905255069377E-6,-0.979739777296629,1.51691806233696E-8,-8.64309312176018E-12,1.51691830856994E-8,-0.0326459758454121,800,25,5,13.4965986394558,-0.0187295144789101,8.92392723222133E-5,4370,0,18.2752552,18.4054184,9.937,9.937,,18.36215,,,,,,,,,,,,,,,,,,,,,,,18.3382971375
,37344179.32,19.347539425,9.937,100,5.00012723378482,,4.07778954346589E-8,1.93696537050239E-6,2.0811269513434E-8,1.93707716817484E-6,0.615577360131466,1.51712941373022E-8,-9.50757738233218E-12,1.51712971164159E-8,-0.035906230619446,800,25,5,13.4965986394558,-0.0187295144789101,8.95672338833884E-5,4370,0,19.2756996,19.414772,9.937,9.937,,19.37915,,,,,,,,,,,,,,,,,,,,,,,19.347539425
,37344272.41,20.0190596625,9.937,100,5.00002166859545,,8.15066059823956E-8,1.99355975194562E-6,-1.43161480450077E-8,1.99361115483244E-6,-0.411445285963794,1.51726719259507E-8,-9.09575717630075E-12,1.51726746523259E-8,-0.0343478352257875,800,25,5,13.4965986394558,-0.0187295144789101,9.00407063037332E-5,4373,0,19.9957428,20.034502,9.937,9.937,,20.0059375,,,,,,,,,,,,,,,,,,,,,,,20.0190596625
,37347064.11,2.4069654625,10.045,300,4.99985787205202,,1.14346255448661E-8,2.19670031675745E-6,2.15909454818114E-8,2.19680642082299E-6,0.563131078357742,1.5162269364519E-8,-8.23314489509623E-11,1.51624928936411E-8,-0.311114258072962,1200,25,5,13.4965986394558,-0.0187295144789101,0.000111255311580215,4370,0,2.3372972,2.4650264,10.045,10.045,,2.404425,,,,,,,,,,,,,,,,,,,,,,,2.4069654625
,37347186.36,3.404617275,10.045,300,4.99985787205202,,1.66448532532257E-8,2.1394647522932E-6,5.59896333189261E-8,2.14019724916751E-6,1.49908412417199,1.51618628754422E-8,-8.21887675852504E-11,1.51620856364562E-8,-0.310583430334702,1200,25,5,13.4965986394558,-0.0187295144789101,0.000111136033363059,4370,0,3.3220351,3.4516213,10.045,10.045,,3.3951125,,,,,,,,,,,,,,,,,,,,,,,3.404617275
,37347308.64,4.3988253,10.045,300,4.99985787205202,,1.62293245586912E-8,2.12817373201855E-6,2.0297788569656E-8,2.12827052647791E-6,0.546450855383809,1.51577895311158E-8,-8.2577339825055E-11,1.51580144638622E-8,-0.31213563424626,1200,25,5,13.4965986394558,-0.0187295144789101,0.000110843512636605,4370,0,4.3168321,4.4582291,10.045,10.045,,4.3946,,,,,,,,,,,,,,,,,,,,,,,4.3988253
,37347430.37,5.3864255,10.045,300,4.99985787205202,,1.21041097257949E-8,2.08292698100897E-6,-3.59200470878481E-8,2.08323667834405E-6,-0.987966998997308,1.51579105567423E-8,-8.20879137880698E-11,1.51581328293359E-8,-0.31028320250374,1200,25,5,13.4965986394558,-0.0187295144789101,0.000110891266752271,4370,0,5.321938,5.455442,10.045,10.045,,5.4020875,,,,,,,,,,,,,,,,,,,,,,,5.3864255
,37347551.37,6.386837625,10.045,300,4.99985787205202,,1.22441850702086E-8,2.13947167533312E-6,6.15428935989758E-8,2.1403566472215E-6,1.64768527335722,1.51580553346409E-8,-8.16280827605873E-11,1.51582751219237E-8,-0.308542179032827,1200,25,5,13.4965986394558,-0.0187295144789101,0.000110974140486632,4370,0,6.31811,6.4516163,10.045,10.045,,6.40095,,,,,,,,,,,,,,,,,,,,,,,6.386837625
,37347670.53,7.3793483375,10.045,300,4.99985787205202,,1.32126869273699E-8,2.06023267130955E-6,6.90883796571374E-10,2.06023278715093E-6,0.0192137153948367,1.5157925536444E-8,-8.28059410402144E-11,1.51581517142511E-8,-0.31299690274426,1200,25,5,13.4965986394558,-0.0187295144789101,0.000111105839056742,4370,0,7.3191109,7.4465675,10.045,10.045,,7.382525,,,,,,,,,,,,,,,,,,,,,,,7.3793483375
,37347764.61,8.152707575,10.045,300,4.99985787205202,,1.36504246261787E-8,1.9849278351945E-6,3.8859027674795E-9,1.98493163891612E-6,0.112168079760718,1.51571980549734E-8,-8.32850608920341E-11,1.51574268686693E-8,-0.314822993302982,1200,25,5,13.4965986394558,-0.0187295144789101,0.0001114883002701,4370,0,8.0973272,8.2284918,10.045,10.045,,8.151875,,,,,,,,,,,,,,,,,,,,,,,8.152707575
,37347878.58,9.1010623,10.045,300,4.99985787205202,,2.6191711553403E-8,1.96864182452865E-6,-1.73477794786819E-8,1.96871825783588E-6,-0.504880476095252,1.51577177099994E-8,-8.1913909598033E-11,1.51579390440988E-8,-0.309629437986416,1200,25,5,13.4965986394558,-0.0187295144789101,0.000110985918407536,4370,0,9.0327959,9.1794224,10.045,10.045,,9.105125,,,,,,,,,,,,,,,,,,,,,,,9.1010623
,37347971.62,9.868919725,10.045,300,4.99985787205202,,1.89431753195835E-8,2.06373029882854E-6,-4.92894040682384E-8,2.06431882025435E-6,-1.36817201138189,1.51570460901734E-8,-8.28164717595212E-11,1.51572723386379E-8,-0.313054869595987,1200,25,5,13.4965986394558,-0.0187295144789101,0.000111081212494851,4370,0,9.805624,9.9279852,10.045,10.045,,9.8751125,,,,,,,,,,,,,,,,,,,,,,,9.868919725
,37348092.48,10.873148075,10.045,300,4.99985787205202,,2.04243961292083E-8,2.02818914604584E-6,5.54619045213508E-8,2.02894732188672E-6,1.56639302338031,1.51580159347542E-8,-8.31370260244868E-11,1.51582439234682E-8,-0.314246466681482,1200,25,5,13.4965986394558,-0.0187295144789101,0.000111423414633119,4370,0,10.8037863,10.9423618,10.045,10.045,,10.876025,,,,,,,,,,,,,,,,,,,,,,,10.873148075
,37348213.61,11.873887075,10.045,300,4.99985787205202,,1.77196344459447E-8,1.98074272339255E-6,1.77372934042214E-8,1.98082213937796E-6,0.513062537856918,1.51575778087333E-8,-8.23474922143614E-11,1.51578014941904E-8,-0.311271193790674,1200,25,5,13.4965986394558,-0.0187295144789101,0.000111231755738407,4370,0,11.7984562,11.9447298,10.045,10.045,,11.8946625,,,,,,,,,,,,,,,,,,,,,,,11.873887075
,37348332.55,12.8607555625,10.045,300,4.99985787205202,,1.6815908398528E-8,1.9355152049542E-6,-1.9400051581941E-8,1.93561242778875E-6,-0.574267695706965,1.51578903311351E-8,-8.22550931556217E-11,1.51581135102976E-8,-0.31091552441859,1200,25,5,13.4965986394558,-0.0187295144789101,0.000111430481385662,4370,0,12.7922382,12.9329557,10.045,10.045,,12.8764,,,,,,,,,,,,,,,,,,,,,,,12.8607555625
,37348452.49,13.856076975,10.045,300,4.99985787205202,,1.76911067840102E-8,2.06674587219038E-6,4.06288262076022E-8,2.06714518158135E-6,1.12619577527629,1.51570409205883E-8,-8.28520485013875E-11,1.51572673635563E-8,-0.313189457515932,1200,25,5,13.4965986394558,-0.0187295144789101,0.000111418703464758,4370,0,13.7870417,13.9234686,10.045,10.045,,13.8732875,,,,,,,,,,,,,,,,,,,,,,,13.856076975
,37348572.37,14.8492279,10.045,300,4.99985787205202,,1.6408027790909E-8,2.01256742335262E-6,3.21671506398713E-9,2.01256999401164E-6,0.0915765792403431,1.51584121957946E-8,-8.28348803140431E-11,1.51586385244523E-8,-0.31309623563601,1200,25,5,13.4965986394558,-0.0187295144789101,0.00011137287664524,4370,0,14.7842655,14.9179544,10.045,10.045,,14.87895,,,,,,,,,,,,,,,,,,,,,,,14.8492279
,37348693.87,15.8575655375,10.045,300,4.99985787205202,,1.59552867596348E-8,2.04741654137705E-6,-1.73679646676407E-8,2.04749020512946E-6,-0.486020888287783,1.51578678826688E-8,-8.27308449055893E-11,1.51580936512855E-8,-0.312714243057258,1200,25,5,13.4965986394558,-0.0187295144789101,0.000111565177972002,4370,0,15.787406,15.9315481,10.045,10.045,,15.8868,,,,,,,,,,,,,,,,,,,,,,,15.8575655375
,37348813.74,16.8570621,10.045,300,4.99985540769616,,2.70385596083755E-8,2.06120009302E-6,8.07322751545667E-9,2.06121590340948E-6,0.224412709801115,1.51594826043984E-8,-8.25196498422517E-11,1.51597071978871E-8,-0.311882739561383,1200,25,5,13.4965986394558,-0.0187295144789101,0.00011147331018895,4370,0,16.7815056,16.9257488,10.045,10.045,,16.8812125,,,,,,,,,,,,,,,,,,,,,,,16.8570621
,37348932.14,17.8439753375,10.045,300,4.99981560157317,,1.6267837955123E-8,2.02558127359371E-6,-1.0408356773488E-8,2.02560801484992E-6,-0.294409152564469,1.51601852164292E-8,-8.34895270129671E-11,1.51604151096716E-8,-0.315533689314805,1200,25,5,13.4965986394558,-0.0187295144789101,0.000111568390132248,4370,0,17.7764988,17.9028912,10.045,10.045,,17.865375,,,,,,,,,,,,,,,,,,,,,,,17.8439753375
,37349052.93,18.84123875,10.045,300,4.99973599786533,,1.4480051399707E-8,2.0040981040486E-6,-3.5978440986517E-8,2.00442102834385E-6,-1.02848827765047,1.51618092483471E-8,-8.31388191924777E-11,1.51620371898542E-8,-0.314174623433018,1200,25,5,13.4965986394558,-0.0187295144789101,0.000111579953909136,4370,0,18.7730312,18.9129639,10.045,10.045,,18.8713875,,,,,,,,,,,,,,,,,,,,,,,18.84123875
,37349173.83,19.84581375,10.045,300,4.99961503109691,,2.03458283985219E-8,2.03431529743949E-6,6.47194720169461E-8,2.03534452598435E-6,1.82218672145072,1.51636368214423E-8,-8.3798867085218E-11,1.51638683686824E-8,-0.316630673227223,1200,25,5,13.4965986394558,-0.0187295144789101,0.000111314415328752,4370,0,19.7714252,19.9129181,10.045,10.045,,19.886325,,,,,,,,,,,,,,,,,,,,,,,19.84581375
,37352202.60,1.9540791125,10.092,1000,4.99895522317214,,3.61599637988643E-9,2.21739356749039E-6,5.30779431433146E-9,2.21739992013805E-6,0.137149144993166,1.51862439043866E-8,-3.06511359486353E-10,1.51893368234763E-8,-1.15627163822569,666,25,5,13.4965986394558,-0.0187295144789101,0.000191140318931833,4370,0,1.8305408,2.1075139,10.092,10.092,,1.8832,,,,,,,,,,,,,,,,,,,,,,,1.9540791125
,37352325.87,2.902663425,10.092,1000,4.99895522317214,,5.04209436543625E-9,2.18026385860966E-6,1.5071281253412E-8,2.18031594881983E-6,0.396056216089855,1.51857253046244E-8,-3.06564012955334E-10,1.5188819391959E-8,-1.15650969548699,666,25,5,13.4965986394558,-0.0187295144789101,0.000190746756955677,4370,0,2.837955,2.9662278,10.092,10.092,,2.9095875,,,,,,,,,,,,,,,,,,,,,,,2.902663425
,37352448.05,3.895266175,10.092,1000,4.99895522317214,,3.81687445023738E-9,2.13849160729314E-6,1.73871398213598E-8,2.13856228973915E-6,0.465836655711761,1.51811905256982E-8,-3.0631673052599E-10,1.51842805465701E-8,-1.15592216724275,666,25,5,13.4965986394558,-0.0187295144789101,0.000190786884843442,4370,0,3.8305988,3.9608102,10.092,10.092,,3.9047875,,,,,,,,,,,,,,,,,,,,,,,3.895266175
,37352569.28,4.8888791375,10.092,1000,4.99895522317214,,3.59680907027154E-9,2.10605963595053E-6,6.47871673971046E-9,2.10606960092744E-6,0.176254246839414,1.51806677816755E-8,-3.06162135630703E-10,1.51837547909236E-8,-1.15537871654868,666,25,5,13.4965986394558,-0.0187295144789101,0.000190512548995356,4370,0,4.8225751,4.951673,10.092,10.092,,4.90115,,,,,,,,,,,,,,,,,,,,,,,4.8888791375
,37352689.97,5.8874498625,10.092,1000,4.99895522317214,,4.07521188314344E-9,2.0739405124686E-6,9.58802227150281E-9,2.07396267551506E-6,0.264881896566808,1.5180962513842E-8,-3.06295885661792E-10,1.51840521606141E-8,-1.1558608836271,666,25,5,13.4965986394558,-0.0187295144789101,0.000190832800407326,4370,0,5.8193345,5.950026,10.092,10.092,,5.89625,,,,,,,,,,,,,,,,,,,,,,,5.8874498625
,37352810.39,6.87977875,10.092,1000,4.99895522317214,,3.88050882191181E-9,2.0846378742146E-6,1.15787061935003E-8,2.0846700297762E-6,0.318234731944505,1.51809997531553E-8,-3.06332857919356E-10,1.51840901382053E-8,-1.15599753209995,666,25,5,13.4965986394558,-0.0187295144789101,0.000190625987447307,4370,0,6.8129067,6.9435201,10.092,10.092,,6.8943375,,,,,,,,,,,,,,,,,,,,,,,6.87977875
,37352936.37,7.9220138875,10.092,1000,4.99895522317214,,3.31390556035205E-9,2.05498873334226E-6,-6.29265152307584E-10,2.05498882968698E-6,-0.0175447367228685,1.51808378459439E-8,-3.06193416083082E-10,1.51839254513743E-8,-1.1554837880737,666,25,5,13.4965986394558,-0.0187295144789101,0.000190712416744031,4370,0,7.8796096,7.9782043,10.092,10.092,,7.927525,,,,,,,,,,,,,,,,,,,,,,,7.9220138875
,37353048.60,8.8653267625,10.092,1000,4.99895522317214,,5.75483099992191E-9,2.03525140264978E-6,1.29628323043691E-8,2.03529268337732E-6,0.364920784635761,1.51810322278504E-8,-3.06261690853563E-10,1.5184121170694E-8,-1.15572657267563,666,25,5,13.4965986394558,-0.0187295144789101,0.000190870227379569,4370,0,8.7996511,8.9399424,10.092,10.092,,8.8666375,,,,,,,,,,,,,,,,,,,,,,,8.8653267625
,37353171.52,9.8776788625,10.092,1000,4.99895522317214,,3.99210878230759E-9,2.02660939814985E-6,2.34685188419866E-8,2.02674527853056E-6,0.663466270838671,1.51811187570942E-8,-3.06065718007106E-10,1.51842037308756E-8,-1.15498065735846,666,25,5,13.4965986394558,-0.0187295144789101,0.000191155366889745,4370,0,9.8024368,9.9353247,10.092,10.092,,9.885025,,,,,,,,,,,,,,,,,,,,,,,9.8776788625
,37353291.29,10.8661163,10.092,1000,4.99895522317214,,3.3958927900734E-9,2.00985907759973E-6,4.2018019584498E-9,2.00986346972866E-6,0.119782113343085,1.51810304498919E-8,-3.06208397868306E-10,1.51841183182782E-8,-1.15552565305683,666,25,5,13.4965986394558,-0.0187295144789101,0.000191117168227353,4370,0,10.8008566,10.9310322,10.092,10.092,,10.8712375,,,,,,,,,,,,,,,,,,,,,,,10.8661163
,37353412.77,11.8625261875,10.092,1000,4.99895522317214,,4.01541675905201E-9,2.00707836135569E-6,-1.49586302237533E-9,2.00707891878432E-6,-0.042702180290064,1.5181036448022E-8,-3.06020704360576E-10,1.51841205312547E-8,-1.15481709773576,666,25,5,13.4965986394558,-0.0187295144789101,0.000191204755059302,4370,0,11.7912378,11.9310923,10.092,10.092,,11.8882625,,,,,,,,,,,,,,,,,,,,,,,11.8625261875
,37353532.87,12.8673176875,10.092,1000,4.99895522317214,,6.12249989676426E-9,2.01774660677873E-6,3.15122306968502E-10,2.0177466313859E-6,0.00894818904032385,1.51807973262727E-8,-3.06349106643178E-10,1.51838880803472E-8,-1.15607424386911,666,25,5,13.4965986394558,-0.0187295144789101,0.000191127586044369,4370,0,12.7939472,12.9368477,10.092,10.092,,12.8855875,,,,,,,,,,,,,,,,,,,,,,,12.8673176875
,37353651.73,13.85490035,10.092,1000,4.99895522317214,,3.91813695399417E-9,2.03009177756432E-6,1.30765446446555E-9,2.0300921987177E-6,0.0369062484470923,1.51810049098261E-8,-3.06353678181851E-10,1.5184095713881E-8,-1.15607568688154,666,25,5,13.4965986394558,-0.0187295144789101,0.000191233693439902,4370,0,13.7874508,13.9274025,10.092,10.092,,13.8714,,,,,,,,,,,,,,,,,,,,,,,13.85490035
,37353712.34,14.3546124625,10.092,1000,4.99895522317214,,6.41691172667239E-9,2.02176732683416E-6,1.37323080665224E-8,2.02181396279157E-6,0.389160110323026,1.51813456127224E-8,-3.06078220154545E-10,1.51844307924195E-8,-1.15501056816885,666,25,5,13.4965986394558,-0.0187295144789101,0.000191271506257219,4370,0,14.2858753,14.4229946,10.092,10.092,,14.3777375,,,,,,,,,,,,,,,,,,,,,,,14.3546124625